Workbook

Sheet LIST HPP
A1: LIST HARGA POKOK PENJUALAN
A4: No. | B4: Nama Produk | C4: HPP
A5: 1 | B5: Matcha Latte | C5: 8805.63
A6: 2 | B6: Hojicha Latte | C6: 8150.63
A7: 3 | B7: Choco Latte | C7: 6013.63
A8: 4 | B8: Matcha Tea | C8: 3748.21
A9: 5 | B9: Ice Tea | C9: 1448.63
A10: 6 | B10: Gyumeshi | C10: 11670
A11: 7 | B11: Karage Don | C11: 9350.16
A12: 8 | B12: Hot Honey Karage Don | C12: 9990.16
A13: 9 | B13: Chicken Katsu Don | C13: 7445.2
A14: 10 | B14: Gyuniku Ala Carte | C14: 17260
A15: 11 | B15: Karage Ala Carte | C15: 14155
A16: 12 | B16: Hot Honey Karage Ala Carte | C16: 15435
... A35: 31 | B35: Gyuniku Bento | C35: 14616.31

Sheet MASTERFILE
A1: PLATFORM | B1: Tanggal | C1: Nama Item | D1: HPP | E1: Jumlah | F1: Jumlah QR | G1: Total Jumlah | H1: Total | I1: Total HPP | J1: Uang Masuk | K1: Margin | L1: Gross Profit
A2: SHOPEE | C2: Matcha Latte | D2: =VLOOKUP(C2, 'LIST HPP'!$B$4:$C$39, 2, ) -> 8805.63 | G2: =sum(E2:F2) -> 0 | H2: =D2*G2 -> 0 | I2: =sum(H2:H32) -> 0 | K2: =(J2-I2)/J2 -> #DIV/0! | L2: =J2-I2 -> 0
C3: Hojicha Latte | D3: =VLOOKUP(C3, 'LIST HPP'!$B$4:$C$39, 2, ) -> 8150.63 | G3: =sum(E3:F3) -> 0 | H3: =D3*G3 -> 0
C4: Choco Latte | D4: =VLOOKUP(C4, 'LIST HPP'!$B$4:$C$39, 2, ) -> 6013.63 | G4: =sum(E4:F4) -> 0 | H4: =D4*G4 -> 0
C5: Choco Ichigo Latte | D5: =VLOOKUP(C5, 'LIST HPP'!$B$4:$C$39, 2, ) -> 7131.43 | G5: =sum(E5:F5) -> 0 | H5: =D5*G5 -> 0
C6: Matcha Tea | D6: =VLOOKUP(C6, 'LIST HPP'!$B$4:$C$39, 2, ) -> 3748.21 | G6: =sum(E6:F6) -> 0 | H6: =D6*G6 -> 0
C7: Ice Tea | D7: =VLOOKUP(C7, 'LIST HPP'!$B$4:$C$39, 2, ) -> 1448.63 | G7: =sum(E7:F7) -> 0 | H7: =D7*G7 -> 0
C8: Gyumeshi | D8: =VLOOKUP(C8, 'LIST HPP'!$B$4:$C$39, 2, ) -> 11670 | G8: =sum(E8:F8) -> 0 | H8: =D8*G8 -> 0
C9: Karage Don | D9: =VLOOKUP(C9, 'LIST HPP'!$B$4:$C$39, 2, ) -> 9350.16 | G9: =sum(E9:F9) -> 0 | H9: =D9*G9 -> 0
C10: Hot Honey Karage Don | D10: =VLOOKUP(C10, 'LIST HPP'!$B$4:$C$39, 2, ) -> 9990.16 | G10: =sum(E10:F10) -> 0 | H10: =D10*G10 -> 0
C11: Chicken Katsu Don | D11: =VLOOKUP(C11, 'LIST HPP'!$B$4:$C$39, 2, ) -> 7445.2 | G11: =sum(E11:F11) -> 0 | H11: =D11*G11 -> 0
C12: Gyuniku Ala Carte | D12: =VLOOKUP(C12, 'LIST HPP'!$B$4:$C$39, 2, ) -> 17260 | G12: =sum(E12:F12) -> 0 | H12: =D12*G12 -> 0
C13: Karage Ala Carte | D13: =VLOOKUP(C13, 'LIST HPP'!$B$4:$C$39, 2, ) -> 14155 | G13: =sum(E13:F13) -> 0 | H13: =D13*G13 -> 0
C14: Hot Honey Karage Ala Carte | D14: =VLOOKUP(C14, 'LIST HPP'!$B$4:$C$39, 2, ) -> 15435 | G14: =sum(E14:F14) -> 0 | H14: =D14*G14 -> 0
... C32: Gyuniku Bento | D32: =VLOOKUP(C32, 'LIST HPP'!$B$4:$C$39, 2, ) -> 14616.31 | G32: =sum(E32:F32) -> 0 | H32: =D32*G32 -> 0
A33: GRAB/ OFFLINE Q | C33: Matcha Latte | D33: =VLOOKUP(C33, 'LIST HPP'!$B$4:$C$39, 2, ) -> 8805.63 | G33: =SUM(E33:F33) -> 0 | H33: =D33*G33 -> 0 | I33: =sum(H33:H63) -> 0 | K33: =(J33-I33)/J33 -> #DIV/0! | L33: =J33-I33 -> 0
C34: Hojicha Latte | D34: =VLOOKUP(C34, 'LIST HPP'!$B$4:$C$39, 2, ) -> 8150.63 | G34: =SUM(E34:F34) -> 0 | H34: =D34*G34 -> 0
C35: Choco Latte | D35: =VLOOKUP(C35, 'LIST HPP'!$B$4:$C$39, 2, ) -> 6013.63 | G35: =SUM(E35:F35) -> 0 | H35: =D35*G35 -> 0
C36: Choco Ichigo Latte | D36: =VLOOKUP(C36, 'LIST HPP'!$B$4:$C$39, 2, ) -> 7131.43 | G36: =SUM(E36:F36) -> 0 | H36: =D36*G36 -> 0
C37: Matcha Tea | D37: =VLOOKUP(C37, 'LIST HPP'!$B$4:$C$39, 2, ) -> 3748.21 | G37: =SUM(E37:F37) -> 0 | H37: =D37*G37 -> 0
C38: Ice Tea | D38: =VLOOKUP(C38, 'LIST HPP'!$B$4:$C$39, 2, ) -> 1448.63 | G38: =SUM(E38:F38) -> 0 | H38: =D38*G38 -> 0
C39: Gyumeshi | D39: =VLOOKUP(C39, 'LIST HPP'!$B$4:$C$39, 2, ) -> 11670 | G39: =SUM(E39:F39) -> 0 | H39: =D39*G39 -> 0
C40: Karage Don | D40: =VLOOKUP(C40, 'LIST HPP'!$B$4:$C$39, 2, ) -> 9350.16 | G40: =SUM(E40:F40) -> 0 | H40: =D40*G40 -> 0
C41: Hot Honey Karage Don | D41: =VLOOKUP(C41, 'LIST HPP'!$B$4:$C$39, 2, ) -> 9990.16 | G41: =SUM(E41:F41) -> 0 | H41: =D41*G41 -> 0
C42: Chicken Katsu Don | D42: =VLOOKUP(C42, 'LIST HPP'!$B$4:$C$39, 2, ) -> 7445.2 | G42: =SUM(E42:F42) -> 0 | H42: =D42*G42 -> 0
C43: Gyuniku Ala Carte | D43: =VLOOKUP(C43, 'LIST HPP'!$B$4:$C$39, 2, ) -> 17260 | G43: =SUM(E43:F43) -> 0 | H43: =D43*G43 -> 0
C44: Karage Ala Carte | D44: =VLOOKUP(C44, 'LIST HPP'!$B$4:$C$39, 2, ) -> 14155 | G44: =SUM(E44:F44) -> 0 | H44: =D44*G44 -> 0
C45: Hot Honey Karage Ala Carte | D45: =VLOOKUP(C45, 'LIST HPP'!$B$4:$C$39, 2, ) -> 15435 | G45: =SUM(E45:F45) -> 0 | H45: =D45*G45 -> 0
... C63: Gyuniku Bento | D63: =VLOOKUP(C63, 'LIST HPP'!$B$4:$C$39, 2, ) -> 14616.31 | G63: =SUM(E63:F63) -> 0 | H63: =D63*G63 -> 0
A64: GOJEK | C64: Matcha Latte | D64: =VLOOKUP(C64, 'LIST HPP'!$B$4:$C$39, 2, ) -> 8805.63 | G64: =Sum(E64:F64) -> 0 | H64: =D64*G64 -> 0 | I64: =sum(H64:H94) -> 0 | K64: =(J64-I64)/J64 -> #DIV/0! | L64: =J64-I64 -> 0
C65: Hojicha Latte | D65: =VLOOKUP(C65, 'LIST HPP'!$B$4:$C$39, 2, ) -> 8150.63 | G65: =Sum(E65:F65) -> 0 | H65: =D65*G65 -> 0
C66: Choco Latte | D66: =VLOOKUP(C66, 'LIST HPP'!$B$4:$C$39, 2, ) -> 6013.63 | G66: =Sum(E66:F66) -> 0 | H66: =D66*G66 -> 0
C67: Choco Ichigo Latte | D67: =VLOOKUP(C67, 'LIST HPP'!$B$4:$C$39, 2, ) -> 7131.43 | G67: =Sum(E67:F67) -> 0 | H67: =D67*G67 -> 0
C68: Matcha Tea | D68: =VLOOKUP(C68, 'LIST HPP'!$B$4:$C$39, 2, ) -> 3748.21 | G68: =Sum(E68:F68) -> 0 | H68: =D68*G68 -> 0
C69: Ice Tea | D69: =VLOOKUP(C69, 'LIST HPP'!$B$4:$C$39, 2, ) -> 1448.63 | G69: =Sum(E69:F69) -> 0 | H69: =D69*G69 -> 0
C70: Gyumeshi | D70: =VLOOKUP(C70, 'LIST HPP'!$B$4:$C$39, 2, ) -> 11670 | G70: =Sum(E70:F70) -> 0 | H70: =D70*G70 -> 0
C71: Karage Don | D71: =VLOOKUP(C71, 'LIST HPP'!$B$4:$C$39, 2, ) -> 9350.16 | G71: =Sum(E71:F71) -> 0 | H71: =D71*G71 -> 0
C72: Hot Honey Karage Don | D72: =VLOOKUP(C72, 'LIST HPP'!$B$4:$C$39, 2, ) -> 9990.16 | G72: =Sum(E72:F72) -> 0 | H72: =D72*G72 -> 0
C73: Chicken Katsu Don | D73: =VLOOKUP(C73, 'LIST HPP'!$B$4:$C$39, 2, ) -> 7445.2 | G73: =Sum(E73:F73) -> 0 | H73: =D73*G73 -> 0
C74: Gyuniku Ala Carte | D74: =VLOOKUP(C74, 'LIST HPP'!$B$4:$C$39, 2, ) -> 17260 | G74: =Sum(E74:F74) -> 0 | H74: =D74*G74 -> 0
...

Sheet 25062026
B1: Tanggal | C1: Nama Item | D1: HPP | E1: Jumlah | F1: Jumlah QR | G1: Total Jumlah | H1: Total | I1: Total HPP | J1: Uang Masuk | K1: Margin | L1: Gross Profit
A2: SHOPEE | C2: Matcha Latte | D2: =VLOOKUP(C2, 'LIST HPP'!$B$4:$C$39, 2, ) -> 8805.63 | E2: 1 | G2: =sum(E2:F2) -> 1 | H2: =D2*G2 -> 8805.63 | I2: =sum(H2:H32) -> 625968.41 | J2: 1014574 | K2: =(J2-I2)/J2 -> 0.38302341 | L2: =J2-I2 -> 388605.59
C3: Hojicha Latte | D3: =VLOOKUP(C3, 'LIST HPP'!$B$4:$C$39, 2, ) -> 8150.63 | E3: 0 | G3: =sum(E3:F3) -> 0 | H3: =D3*G3 -> 0
C4: Choco Latte | D4: =VLOOKUP(C4, 'LIST HPP'!$B$4:$C$39, 2, ) -> 6013.63 | E4: 0 | G4: =sum(E4:F4) -> 0 | H4: =D4*G4 -> 0
C5: Choco Ichigo Latte | D5: =VLOOKUP(C5, 'LIST HPP'!$B$4:$C$39, 2, ) -> 7131.43 | E5: 0 | G5: =sum(E5:F5) -> 0 | H5: =D5*G5 -> 0
C6: Matcha Tea | D6: =VLOOKUP(C6, 'LIST HPP'!$B$4:$C$39, 2, ) -> 3748.21 | E6: 3 | G6: =sum(E6:F6) -> 3 | H6: =D6*G6 -> 11244.63
C7: Ice Tea | D7: =VLOOKUP(C7, 'LIST HPP'!$B$4:$C$39, 2, ) -> 1448.63 | E7: 7 | G7: =sum(E7:F7) -> 7 | H7: =D7*G7 -> 10140.41
C8: Gyumeshi | D8: =VLOOKUP(C8, 'LIST HPP'!$B$4:$C$39, 2, ) -> 11670 | E8: 5 | G8: =sum(E8:F8) -> 5 | H8: =D8*G8 -> 58350
C9: Karage Don | D9: =VLOOKUP(C9, 'LIST HPP'!$B$4:$C$39, 2, ) -> 9350.16 | E9: 19 | G9: =sum(E9:F9) -> 19 | H9: =D9*G9 -> 177653.04
C10: Hot Honey Karage Don | D10: =VLOOKUP(C10, 'LIST HPP'!$B$4:$C$39, 2, ) -> 9990.16 | E10: 2 | G10: =sum(E10:F10) -> 2 | H10: =D10*G10 -> 19980.32
C11: Chicken Katsu Don | D11: =VLOOKUP(C11, 'LIST HPP'!$B$4:$C$39, 2, ) -> 7445.2 | E11: 28 | G11: =sum(E11:F11) -> 28 | H11: =D11*G11 -> 208465.6
C12: Gyuniku Ala Carte | D12: =VLOOKUP(C12, 'LIST HPP'!$B$4:$C$39, 2, ) -> 17260 | E12: 0 | G12: =sum(E12:F12) -> 0 | H12: =D12*G12 -> 0
C13: Karage Ala Carte | D13: =VLOOKUP(C13, 'LIST HPP'!$B$4:$C$39, 2, ) -> 14155 | E13: 0 | G13: =sum(E13:F13) -> 0 | H13: =D13*G13 -> 0
C14: Hot Honey Karage Ala Carte | D14: =VLOOKUP(C14, 'LIST HPP'!$B$4:$C$39, 2, ) -> 15435 | E14: 0 | G14: =sum(E14:F14) -> 0 | H14: =D14*G14 -> 0
... C32: Gyuniku Bento | D32: =VLOOKUP(C32, 'LIST HPP'!$B$4:$C$39, 2, ) -> 14616.31 | E32: 0 | G32: =sum(E32:F32) -> 0 | H32: =D32*G32 -> 0
A33: GRAB/ OFFLINE Q | C33: Matcha Latte | D33: =VLOOKUP(C33, 'LIST HPP'!$B$4:$C$39, 2, ) -> 8805.63 | E33: 0 | G33: =SUM(E33:F33) -> 0 | H33: =D33*G33 -> 0 | I33: =sum(H33:H63) -> 153667 | J33: 323442 | K33: =(J33-I33)/J33 -> 0.52490091 | L33: =J33-I33 -> 169775
C34: Hojicha Latte | D34: =VLOOKUP(C34, 'LIST HPP'!$B$4:$C$39, 2, ) -> 8150.63 | E34: 0 | G34: =SUM(E34:F34) -> 0 | H34: =D34*G34 -> 0
C35: Choco Latte | D35: =VLOOKUP(C35, 'LIST HPP'!$B$4:$C$39, 2, ) -> 6013.63 | E35: 0 | G35: =SUM(E35:F35) -> 0 | H35: =D35*G35 -> 0
C36: Choco Ichigo Latte | D36: =VLOOKUP(C36, 'LIST HPP'!$B$4:$C$39, 2, ) -> 7131.43 | E36: 0 | G36: =SUM(E36:F36) -> 0 | H36: =D36*G36 -> 0
C37: Matcha Tea | D37: =VLOOKUP(C37, 'LIST HPP'!$B$4:$C$39, 2, ) -> 3748.21 | E37: 0 | G37: =SUM(E37:F37) -> 0 | H37: =D37*G37 -> 0
C38: Ice Tea | D38: =VLOOKUP(C38, 'LIST HPP'!$B$4:$C$39, 2, ) -> 1448.63 | E38: 0 | G38: =SUM(E38:F38) -> 0 | H38: =D38*G38 -> 0
C39: Gyumeshi | D39: =VLOOKUP(C39, 'LIST HPP'!$B$4:$C$39, 2, ) -> 11670 | E39: 2 | G39: =SUM(E39:F39) -> 2 | H39: =D39*G39 -> 23340
C40: Karage Don | D40: =VLOOKUP(C40, 'LIST HPP'!$B$4:$C$39, 2, ) -> 9350.16 | E40: 8 | G40: =SUM(E40:F40) -> 8 | H40: =D40*G40 -> 74801.28
C41: Hot Honey Karage Don | D41: =VLOOKUP(C41, 'LIST HPP'!$B$4:$C$39, 2, ) -> 9990.16 | E41: 2 | G41: =SUM(E41:F41) -> 2 | H41: =D41*G41 -> 19980.32
C42: Chicken Katsu Don | D42: =VLOOKUP(C42, 'LIST HPP'!$B$4:$C$39, 2, ) -> 7445.2 | E42: 2 | G42: =SUM(E42:F42) -> 2 | H42: =D42*G42 -> 14890.4
C43: Gyuniku Ala Carte | D43: =VLOOKUP(C43, 'LIST HPP'!$B$4:$C$39, 2, ) -> 17260 | E43: 0 | G43: =SUM(E43:F43) -> 0 | H43: =D43*G43 -> 0
C44: Karage Ala Carte | D44: =VLOOKUP(C44, 'LIST HPP'!$B$4:$C$39, 2, ) -> 14155 | E44: 1 | G44: =SUM(E44:F44) -> 1 | H44: =D44*G44 -> 14155
C45: Hot Honey Karage Ala Carte | D45: =VLOOKUP(C45, 'LIST HPP'!$B$4:$C$39, 2, ) -> 15435 | E45: 0 | G45: =SUM(E45:F45) -> 0 | H45: =D45*G45 -> 0
... C63: Gyuniku Bento | D63: =VLOOKUP(C63, 'LIST HPP'!$B$4:$C$39, 2, ) -> 14616.31 | E63: 0 | G63: =SUM(E63:F63) -> 0 | H63: =D63*G63 -> 0
A64: GOJEK | C64: Matcha Latte | D64: =VLOOKUP(C64, 'LIST HPP'!$B$4:$C$39, 2, ) -> 8805.63 | E64: 0 | G64: =Sum(E64:F64) -> 0 | H64: =D64*G64 -> 0 | I64: =sum(H64:H94) -> 19764.66 | J64: 19439 | K64: =(J64-I64)/J64 -> -0.016752919 | L64: =J64-I64 -> -325.66
C65: Hojicha Latte | D65: =VLOOKUP(C65, 'LIST HPP'!$B$4:$C$39, 2, ) -> 8150.63 | E65: 0 | G65: =Sum(E65:F65) -> 0 | H65: =D65*G65 -> 0
C66: Choco Latte | D66: =VLOOKUP(C66, 'LIST HPP'!$B$4:$C$39, 2, ) -> 6013.63 | E66: 0 | G66: =Sum(E66:F66) -> 0 | H66: =D66*G66 -> 0
C67: Choco Ichigo Latte | D67: =VLOOKUP(C67, 'LIST HPP'!$B$4:$C$39, 2, ) -> 7131.43 | E67: 0 | G67: =Sum(E67:F67) -> 0 | H67: =D67*G67 -> 0
C68: Matcha Tea | D68: =VLOOKUP(C68, 'LIST HPP'!$B$4:$C$39, 2, ) -> 3748.21 | E68: 0 | G68: =Sum(E68:F68) -> 0 | H68: =D68*G68 -> 0
C69: Ice Tea | D69: =VLOOKUP(C69, 'LIST HPP'!$B$4:$C$39, 2, ) -> 1448.63 | E69: 2 | G69: =Sum(E69:F69) -> 2 | H69: =D69*G69 -> 2897.26
C70: Gyumeshi | D70: =VLOOKUP(C70, 'LIST HPP'!$B$4:$C$39, 2, ) -> 11670 | E70: 0 | G70: =Sum(E70:F70) -> 0 | H70: =D70*G70 -> 0
C71: Karage Don | D71: =VLOOKUP(C71, 'LIST HPP'!$B$4:$C$39, 2, ) -> 9350.16 | E71: 0 | G71: =Sum(E71:F71) -> 0 | H71: =D71*G71 -> 0
C72: Hot Honey Karage Don | D72: =VLOOKUP(C72, 'LIST HPP'!$B$4:$C$39, 2, ) -> 9990.16 | E72: 0 | G72: =Sum(E72:F72) -> 0 | H72: =D72*G72 -> 0
C73: Chicken Katsu Don | D73: =VLOOKUP(C73, 'LIST HPP'!$B$4:$C$39, 2, ) -> 7445.2 | E73: 2 | G73: =Sum(E73:F73) -> 2 | H73: =D73*G73 -> 14890.4
C74: Gyuniku Ala Carte | D74: =VLOOKUP(C74, 'LIST HPP'!$B$4:$C$39, 2, ) -> 17260 | E74: 0 | G74: =Sum(E74:F74) -> 0 | H74: =D74*G74 -> 0
...

Sheet 24062026
B1: Tanggal | C1: Nama Item | D1: HPP | E1: Jumlah | F1: Jumlah QR | G1: Total Jumlah | H1: Total | I1: Total HPP | J1: Uang Masuk | K1: Margin | L1: Gross Profit
A2: SHOPEE | C2: Matcha Latte | D2: =VLOOKUP(C2, 'LIST HPP'!$B$4:$C$39, 2, ) -> 8805.63 | E2: 2 | G2: =sum(E2:F2) -> 2 | H2: =D2*G2 -> 17611.26 | I2: =sum(H2:H32) -> 360944.36 | J2: 561388 | K2: =(J2-I2)/J2 -> 0.3570501 | L2: =J2-I2 -> 200443.64
C3: Hojicha Latte | D3: =VLOOKUP(C3, 'LIST HPP'!$B$4:$C$39, 2, ) -> 8150.63 | E3: 0 | G3: =sum(E3:F3) -> 0 | H3: =D3*G3 -> 0
C4: Choco Latte | D4: =VLOOKUP(C4, 'LIST HPP'!$B$4:$C$39, 2, ) -> 6013.63 | E4: 0 | G4: =sum(E4:F4) -> 0 | H4: =D4*G4 -> 0
C5: Choco Ichigo Latte | D5: =VLOOKUP(C5, 'LIST HPP'!$B$4:$C$39, 2, ) -> 7131.43 | E5: 0 | G5: =sum(E5:F5) -> 0 | H5: =D5*G5 -> 0
C6: Matcha Tea | D6: =VLOOKUP(C6, 'LIST HPP'!$B$4:$C$39, 2, ) -> 3748.21 | E6: 2 | G6: =sum(E6:F6) -> 2 | H6: =D6*G6 -> 7496.42
C7: Ice Tea | D7: =VLOOKUP(C7, 'LIST HPP'!$B$4:$C$39, 2, ) -> 1448.63 | E7: 2 | G7: =sum(E7:F7) -> 2 | H7: =D7*G7 -> 2897.26
C8: Gyumeshi | D8: =VLOOKUP(C8, 'LIST HPP'!$B$4:$C$39, 2, ) -> 11670 | E8: 2 | G8: =sum(E8:F8) -> 2 | H8: =D8*G8 -> 23340
C9: Karage Don | D9: =VLOOKUP(C9, 'LIST HPP'!$B$4:$C$39, 2, ) -> 9350.16 | E9: 6 | G9: =sum(E9:F9) -> 6 | H9: =D9*G9 -> 56100.96
C10: Hot Honey Karage Don | D10: =VLOOKUP(C10, 'LIST HPP'!$B$4:$C$39, 2, ) -> 9990.16 | E10: 4 | G10: =sum(E10:F10) -> 4 | H10: =D10*G10 -> 39960.64
C11: Chicken Katsu Don | D11: =VLOOKUP(C11, 'LIST HPP'!$B$4:$C$39, 2, ) -> 7445.2 | E11: 20 | G11: =sum(E11:F11) -> 20 | H11: =D11*G11 -> 148904
C12: Gyuniku Ala Carte | D12: =VLOOKUP(C12, 'LIST HPP'!$B$4:$C$39, 2, ) -> 17260 | E12: 0 | G12: =sum(E12:F12) -> 0 | H12: =D12*G12 -> 0
C13: Karage Ala Carte | D13: =VLOOKUP(C13, 'LIST HPP'!$B$4:$C$39, 2, ) -> 14155 | E13: 1 | G13: =sum(E13:F13) -> 1 | H13: =D13*G13 -> 14155
C14: Hot Honey Karage Ala Carte | D14: =VLOOKUP(C14, 'LIST HPP'!$B$4:$C$39, 2, ) -> 15435 | E14: 0 | G14: =sum(E14:F14) -> 0 | H14: =D14*G14 -> 0
... C32: Gyuniku Bento | D32: =VLOOKUP(C32, 'LIST HPP'!$B$4:$C$39, 2, ) -> 14616.31 | E32: 0 | G32: =sum(E32:F32) -> 0 | H32: =D32*G32 -> 0
A33: GRAB/ OFFLINE Q | C33: Matcha Latte | D33: =VLOOKUP(C33, 'LIST HPP'!$B$4:$C$39, 2, ) -> 8805.63 | E33: 0 | G33: =SUM(E33:F33) -> 0 | H33: =D33*G33 -> 0 | I33: =sum(H33:H63) -> 87737.28 | J33: 169646 | K33: =(J33-I33)/J33 -> 0.4828214 | L33: =J33-I33 -> 81908.72
C34: Hojicha Latte | D34: =VLOOKUP(C34, 'LIST HPP'!$B$4:$C$39, 2, ) -> 8150.63 | E34: 0 | G34: =SUM(E34:F34) -> 0 | H34: =D34*G34 -> 0
C35: Choco Latte | D35: =VLOOKUP(C35, 'LIST HPP'!$B$4:$C$39, 2, ) -> 6013.63 | E35: 0 | G35: =SUM(E35:F35) -> 0 | H35: =D35*G35 -> 0
C36: Choco Ichigo Latte | D36: =VLOOKUP(C36, 'LIST HPP'!$B$4:$C$39, 2, ) -> 7131.43 | E36: 0 | G36: =SUM(E36:F36) -> 0 | H36: =D36*G36 -> 0
C37: Matcha Tea | D37: =VLOOKUP(C37, 'LIST HPP'!$B$4:$C$39, 2, ) -> 3748.21 | E37: 1 | G37: =SUM(E37:F37) -> 1 | H37: =D37*G37 -> 3748.21
C38: Ice Tea | D38: =VLOOKUP(C38, 'LIST HPP'!$B$4:$C$39, 2, ) -> 1448.63 | E38: 1 | G38: =SUM(E38:F38) -> 1 | H38: =D38*G38 -> 1448.63
C39: Gyumeshi | D39: =VLOOKUP(C39, 'LIST HPP'!$B$4:$C$39, 2, ) -> 11670 | E39: 0 | G39: =SUM(E39:F39) -> 0 | H39: =D39*G39 -> 0
C40: Karage Don | D40: =VLOOKUP(C40, 'LIST HPP'!$B$4:$C$39, 2, ) -> 9350.16 | E40: 0 | G40: =SUM(E40:F40) -> 0 | H40: =D40*G40 -> 0
C41: Hot Honey Karage Don | D41: =VLOOKUP(C41, 'LIST HPP'!$B$4:$C$39, 2, ) -> 9990.16 | E41: 2 | G41: =SUM(E41:F41) -> 2 | H41: =D41*G41 -> 19980.32
C42: Chicken Katsu Don | D42: =VLOOKUP(C42, 'LIST HPP'!$B$4:$C$39, 2, ) -> 7445.2 | E42: 4 | G42: =SUM(E42:F42) -> 4 | H42: =D42*G42 -> 29780.8
C43: Gyuniku Ala Carte | D43: =VLOOKUP(C43, 'LIST HPP'!$B$4:$C$39, 2, ) -> 17260 | E43: 0 | G43: =SUM(E43:F43) -> 0 | H43: =D43*G43 -> 0
C44: Karage Ala Carte | D44: =VLOOKUP(C44, 'LIST HPP'!$B$4:$C$39, 2, ) -> 14155 | E44: 0 | G44: =SUM(E44:F44) -> 0 | H44: =D44*G44 -> 0
C45: Hot Honey Karage Ala Carte | D45: =VLOOKUP(C45, 'LIST HPP'!$B$4:$C$39, 2, ) -> 15435 | E45: 0 | G45: =SUM(E45:F45) -> 0 | H45: =D45*G45 -> 0
... C63: Gyuniku Bento | D63: =VLOOKUP(C63, 'LIST HPP'!$B$4:$C$39, 2, ) -> 14616.31 | E63: 0 | G63: =SUM(E63:F63) -> 0 | H63: =D63*G63 -> 0
A64: GOJEK | C64: Matcha Latte | D64: =VLOOKUP(C64, 'LIST HPP'!$B$4:$C$39, 2, ) -> 8805.63 | E64: 2 | G64: =Sum(E64:F64) -> 2 | H64: =D64*G64 -> 17611.26 | I64: =sum(H64:H94) -> 68089.19 | J64: 114232 | K64: =(J64-I64)/J64 -> 0.40393944 | L64: =J64-I64 -> 46142.81
C65: Hojicha Latte | D65: =VLOOKUP(C65, 'LIST HPP'!$B$4:$C$39, 2, ) -> 8150.63 | E65: 0 | G65: =Sum(E65:F65) -> 0 | H65: =D65*G65 -> 0
C66: Choco Latte | D66: =VLOOKUP(C66, 'LIST HPP'!$B$4:$C$39, 2, ) -> 6013.63 | E66: 0 | G66: =Sum(E66:F66) -> 0 | H66: =D66*G66 -> 0
C67: Choco Ichigo Latte | D67: =VLOOKUP(C67, 'LIST HPP'!$B$4:$C$39, 2, ) -> 7131.43 | E67: 0 | G67: =Sum(E67:F67) -> 0 | H67: =D67*G67 -> 0
C68: Matcha Tea | D68: =VLOOKUP(C68, 'LIST HPP'!$B$4:$C$39, 2, ) -> 3748.21 | E68: 0 | G68: =Sum(E68:F68) -> 0 | H68: =D68*G68 -> 0
C69: Ice Tea | D69: =VLOOKUP(C69, 'LIST HPP'!$B$4:$C$39, 2, ) -> 1448.63 | E69: 1 | G69: =Sum(E69:F69) -> 1 | H69: =D69*G69 -> 1448.63
C70: Gyumeshi | D70: =VLOOKUP(C70, 'LIST HPP'!$B$4:$C$39, 2, ) -> 11670 | E70: 0 | G70: =Sum(E70:F70) -> 0 | H70: =D70*G70 -> 0
C71: Karage Don | D71: =VLOOKUP(C71, 'LIST HPP'!$B$4:$C$39, 2, ) -> 9350.16 | E71: 1 | G71: =Sum(E71:F71) -> 1 | H71: =D71*G71 -> 9350.16
C72: Hot Honey Karage Don | D72: =VLOOKUP(C72, 'LIST HPP'!$B$4:$C$39, 2, ) -> 9990.16 | E72: 1 | G72: =Sum(E72:F72) -> 1 | H72: =D72*G72 -> 9990.16
C73: Chicken Katsu Don | D73: =VLOOKUP(C73, 'LIST HPP'!$B$4:$C$39, 2, ) -> 7445.2 | E73: 0 | G73: =Sum(E73:F73) -> 0 | H73: =D73*G73 -> 0
C74: Gyuniku Ala Carte | D74: =VLOOKUP(C74, 'LIST HPP'!$B$4:$C$39, 2, ) -> 17260 | E74: 0 | G74: =Sum(E74:F74) -> 0 | H74: =D74*G74 -> 0
...

Sheet 23062026
A1: PLATFORM | B1: Tanggal | C1: Nama Item | D1: HPP | E1: Jumlah | F1: Jumlah QR | G1: Total Jumlah | H1: Total | I1: Total HPP | J1: Uang Masuk | K1: Margin | L1: Gross Profit
A2: SHOPEE | C2: Matcha Latte | D2: =VLOOKUP(C2, 'LIST HPP'!$B$4:$C$39, 2, ) -> 8805.63 | E2: 1 | G2: =sum(E2:F2) -> 1 | H2: =D2*G2 -> 8805.63 | I2: =sum(H2:H32) -> 608382.22 | J2: 977502 | K2: =(J2-I2)/J2 -> 0.37761537 | L2: =J2-I2 -> 369119.78
C3: Hojicha Latte | D3: =VLOOKUP(C3, 'LIST HPP'!$B$4:$C$39, 2, ) -> 8150.63 | E3: 0 | G3: =sum(E3:F3) -> 0 | H3: =D3*G3 -> 0
C4: Choco Latte | D4: =VLOOKUP(C4, 'LIST HPP'!$B$4:$C$39, 2, ) -> 6013.63 | E4: 0 | G4: =sum(E4:F4) -> 0 | H4: =D4*G4 -> 0
C5: Choco Ichigo Latte | D5: =VLOOKUP(C5, 'LIST HPP'!$B$4:$C$39, 2, ) -> 7131.43 | E5: 0 | G5: =sum(E5:F5) -> 0 | H5: =D5*G5 -> 0
C6: Matcha Tea | D6: =VLOOKUP(C6, 'LIST HPP'!$B$4:$C$39, 2, ) -> 3748.21 | E6: 1 | G6: =sum(E6:F6) -> 1 | H6: =D6*G6 -> 3748.21
C7: Ice Tea | D7: =VLOOKUP(C7, 'LIST HPP'!$B$4:$C$39, 2, ) -> 1448.63 | E7: 4 | G7: =sum(E7:F7) -> 4 | H7: =D7*G7 -> 5794.52
C8: Gyumeshi | D8: =VLOOKUP(C8, 'LIST HPP'!$B$4:$C$39, 2, ) -> 11670 | E8: 10 | G8: =sum(E8:F8) -> 10 | H8: =D8*G8 -> 116700
C9: Karage Don | D9: =VLOOKUP(C9, 'LIST HPP'!$B$4:$C$39, 2, ) -> 9350.16 | E9: 4 | G9: =sum(E9:F9) -> 4 | H9: =D9*G9 -> 37400.64
C10: Hot Honey Karage Don | D10: =VLOOKUP(C10, 'LIST HPP'!$B$4:$C$39, 2, ) -> 9990.16 | E10: 4 | G10: =sum(E10:F10) -> 4 | H10: =D10*G10 -> 39960.64
C11: Chicken Katsu Don | D11: =VLOOKUP(C11, 'LIST HPP'!$B$4:$C$39, 2, ) -> 7445.2 | E11: 37 | G11: =sum(E11:F11) -> 37 | H11: =D11*G11 -> 275472.4
C12: Gyuniku Ala Carte | D12: =VLOOKUP(C12, 'LIST HPP'!$B$4:$C$39, 2, ) -> 17260 | E12: 1 | G12: =sum(E12:F12) -> 1 | H12: =D12*G12 -> 17260
C13: Karage Ala Carte | D13: =VLOOKUP(C13, 'LIST HPP'!$B$4:$C$39, 2, ) -> 14155 | E13: 2 | G13: =sum(E13:F13) -> 2 | H13: =D13*G13 -> 28310
C14: Hot Honey Karage Ala Carte | D14: =VLOOKUP(C14, 'LIST HPP'!$B$4:$C$39, 2, ) -> 15435 | E14: 0 | G14: =sum(E14:F14) -> 0 | H14: =D14*G14 -> 0
... C32: Gyuniku Bento | D32: =VLOOKUP(C32, 'LIST HPP'!$B$4:$C$39, 2, ) -> 14616.31 | E32: 0 | G32: =sum(E32:F32) -> 0 | H32: =D32*G32 -> 0
A33: GRAB/ OFFLINE Q | C33: Matcha Latte | D33: =VLOOKUP(C33, 'LIST HPP'!$B$4:$C$39, 2, ) -> 8805.63 | E33: 0 | F33: 0 | G33: =SUM(E33:F33) -> 0 | H33: =D33*G33 -> 0 | I33: =sum(H33:H63) -> 164609.05 | J33: 236017 | K33: =(J33-I33)/J33 -> 0.30255427 | L33: =J33-I33 -> 71407.95
C34: Hojicha Latte | D34: =VLOOKUP(C34, 'LIST HPP'!$B$4:$C$39, 2, ) -> 8150.63 | E34: 0 | F34: 0 | G34: =SUM(E34:F34) -> 0 | H34: =D34*G34 -> 0
C35: Choco Latte | D35: =VLOOKUP(C35, 'LIST HPP'!$B$4:$C$39, 2, ) -> 6013.63 | E35: 0 | F35: 0 | G35: =SUM(E35:F35) -> 0 | H35: =D35*G35 -> 0
C36: Choco Ichigo Latte | D36: =VLOOKUP(C36, 'LIST HPP'!$B$4:$C$39, 2, ) -> 7131.43 | E36: 0 | F36: 0 | G36: =SUM(E36:F36) -> 0 | H36: =D36*G36 -> 0
C37: Matcha Tea | D37: =VLOOKUP(C37, 'LIST HPP'!$B$4:$C$39, 2, ) -> 3748.21 | E37: 0 | F37: 0 | G37: =SUM(E37:F37) -> 0 | H37: =D37*G37 -> 0
C38: Ice Tea | D38: =VLOOKUP(C38, 'LIST HPP'!$B$4:$C$39, 2, ) -> 1448.63 | E38: 1 | F38: 0 | G38: =SUM(E38:F38) -> 1 | H38: =D38*G38 -> 1448.63
C39: Gyumeshi | D39: =VLOOKUP(C39, 'LIST HPP'!$B$4:$C$39, 2, ) -> 11670 | E39: 0 | F39: 0 | G39: =SUM(E39:F39) -> 0 | H39: =D39*G39 -> 0
C40: Karage Don | D40: =VLOOKUP(C40, 'LIST HPP'!$B$4:$C$39, 2, ) -> 9350.16 | E40: 2 | F40: 0 | G40: =SUM(E40:F40) -> 2 | H40: =D40*G40 -> 18700.32
C41: Hot Honey Karage Don | D41: =VLOOKUP(C41, 'LIST HPP'!$B$4:$C$39, 2, ) -> 9990.16 | E41: 3 | F41: 0 | G41: =SUM(E41:F41) -> 3 | H41: =D41*G41 -> 29970.48
C42: Chicken Katsu Don | D42: =VLOOKUP(C42, 'LIST HPP'!$B$4:$C$39, 2, ) -> 7445.2 | E42: 9 | F42: 0 | G42: =SUM(E42:F42) -> 9 | H42: =D42*G42 -> 67006.8
C43: Gyuniku Ala Carte | D43: =VLOOKUP(C43, 'LIST HPP'!$B$4:$C$39, 2, ) -> 17260 | E43: 0 | F43: 0 | G43: =SUM(E43:F43) -> 0 | H43: =D43*G43 -> 0
C44: Karage Ala Carte | D44: =VLOOKUP(C44, 'LIST HPP'!$B$4:$C$39, 2, ) -> 14155 | E44: 0 | F44: 0 | G44: =SUM(E44:F44) -> 0 | H44: =D44*G44 -> 0
C45: Hot Honey Karage Ala Carte | D45: =VLOOKUP(C45, 'LIST HPP'!$B$4:$C$39, 2, ) -> 15435 | E45: 0 | F45: 0 | G45: =SUM(E45:F45) -> 0 | H45: =D45*G45 -> 0
... C63: Gyuniku Bento | D63: =VLOOKUP(C63, 'LIST HPP'!$B$4:$C$39, 2, ) -> 14616.31 | E63: 0 | F63: 0 | G63: =SUM(E63:F63) -> 0 | H63: =D63*G63 -> 0
A64: GOJEK | C64: Matcha Latte | D64: =VLOOKUP(C64, 'LIST HPP'!$B$4:$C$39, 2, ) -> 8805.63 | E64: 0 | G64: =Sum(E64:F64) -> 0 | H64: =D64*G64 -> 0 | I64: =sum(H64:H94) -> 77609.48 | J64: 162602 | K64: =(J64-I64)/J64 -> 0.5227028 | L64: =J64-I64 -> 84992.52
C65: Hojicha Latte | D65: =VLOOKUP(C65, 'LIST HPP'!$B$4:$C$39, 2, ) -> 8150.63 | E65: 0 | G65: =Sum(E65:F65) -> 0 | H65: =D65*G65 -> 0
C66: Choco Latte | D66: =VLOOKUP(C66, 'LIST HPP'!$B$4:$C$39, 2, ) -> 6013.63 | E66: 0 | G66: =Sum(E66:F66) -> 0 | H66: =D66*G66 -> 0
C67: Choco Ichigo Latte | D67: =VLOOKUP(C67, 'LIST HPP'!$B$4:$C$39, 2, ) -> 7131.43 | E67: 0 | G67: =Sum(E67:F67) -> 0 | H67: =D67*G67 -> 0
C68: Matcha Tea | D68: =VLOOKUP(C68, 'LIST HPP'!$B$4:$C$39, 2, ) -> 3748.21 | E68: 0 | G68: =Sum(E68:F68) -> 0 | H68: =D68*G68 -> 0
C69: Ice Tea | D69: =VLOOKUP(C69, 'LIST HPP'!$B$4:$C$39, 2, ) -> 1448.63 | E69: 2 | G69: =Sum(E69:F69) -> 2 | H69: =D69*G69 -> 2897.26
C70: Gyumeshi | D70: =VLOOKUP(C70, 'LIST HPP'!$B$4:$C$39, 2, ) -> 11670 | E70: 1 | G70: =Sum(E70:F70) -> 1 | H70: =D70*G70 -> 11670
C71: Karage Don | D71: =VLOOKUP(C71, 'LIST HPP'!$B$4:$C$39, 2, ) -> 9350.16 | E71: 2 | G71: =Sum(E71:F71) -> 2 | H71: =D71*G71 -> 18700.32
C72: Hot Honey Karage Don | D72: =VLOOKUP(C72, 'LIST HPP'!$B$4:$C$39, 2, ) -> 9990.16 | E72: 2 | G72: =Sum(E72:F72) -> 2 | H72: =D72*G72 -> 19980.32
C73: Chicken Katsu Don | D73: =VLOOKUP(C73, 'LIST HPP'!$B$4:$C$39, 2, ) -> 7445.2 | E73: 2 | G73: =Sum(E73:F73) -> 2 | H73: =D73*G73 -> 14890.4
C74: Gyuniku Ala Carte | D74: =VLOOKUP(C74, 'LIST HPP'!$B$4:$C$39, 2, ) -> 17260 | E74: 0 | G74: =Sum(E74:F74) -> 0 | H74: =D74*G74 -> 0
...

Sheet 22062026
A1: PLATFORM | B1: Tanggal | C1: Nama Item | D1: HPP | E1: Jumlah | F1: Jumlah QR | G1: Total Jumlah | H1: Total | I1: Total HPP | J1: Uang Masuk | K1: Margin | L1: Gross Profit
A2: SHOPEE | C2: Matcha Latte | D2: =VLOOKUP(C2, 'LIST HPP'!$B$4:$C$39, 2, ) -> 8805.63 | E2: 1 | G2: =sum(E2:F2) -> 1 | H2: =D2*G2 -> 8805.63 | I2: =sum(H2:H32) -> 610271.36 | J2: 971818 | K2: =(J2-I2)/J2 -> 0.37203122 | L2: =J2-I2 -> 361546.64
C3: Hojicha Latte | D3: =VLOOKUP(C3, 'LIST HPP'!$B$4:$C$39, 2, ) -> 8150.63 | E3: 0 | G3: =sum(E3:F3) -> 0 | H3: =D3*G3 -> 0
C4: Choco Latte | D4: =VLOOKUP(C4, 'LIST HPP'!$B$4:$C$39, 2, ) -> 6013.63 | E4: 0 | G4: =sum(E4:F4) -> 0 | H4: =D4*G4 -> 0
C5: Choco Ichigo Latte | D5: =VLOOKUP(C5, 'LIST HPP'!$B$4:$C$39, 2, ) -> 7131.43 | E5: 0 | G5: =sum(E5:F5) -> 0 | H5: =D5*G5 -> 0
C6: Matcha Tea | D6: =VLOOKUP(C6, 'LIST HPP'!$B$4:$C$39, 2, ) -> 3748.21 | E6: 5 | G6: =sum(E6:F6) -> 5 | H6: =D6*G6 -> 18741.05
C7: Ice Tea | D7: =VLOOKUP(C7, 'LIST HPP'!$B$4:$C$39, 2, ) -> 1448.63 | E7: 6 | G7: =sum(E7:F7) -> 6 | H7: =D7*G7 -> 8691.78
C8: Gyumeshi | D8: =VLOOKUP(C8, 'LIST HPP'!$B$4:$C$39, 2, ) -> 11670 | E8: 9 | G8: =sum(E8:F8) -> 9 | H8: =D8*G8 -> 105030
C9: Karage Don | D9: =VLOOKUP(C9, 'LIST HPP'!$B$4:$C$39, 2, ) -> 9350.16 | E9: 17 | G9: =sum(E9:F9) -> 17 | H9: =D9*G9 -> 158952.72
C10: Hot Honey Karage Don | D10: =VLOOKUP(C10, 'LIST HPP'!$B$4:$C$39, 2, ) -> 9990.16 | E10: 3 | G10: =sum(E10:F10) -> 3 | H10: =D10*G10 -> 29970.48
C11: Chicken Katsu Don | D11: =VLOOKUP(C11, 'LIST HPP'!$B$4:$C$39, 2, ) -> 7445.2 | E11: 22 | G11: =sum(E11:F11) -> 22 | H11: =D11*G11 -> 163794.4
C12: Gyuniku Ala Carte | D12: =VLOOKUP(C12, 'LIST HPP'!$B$4:$C$39, 2, ) -> 17260 | E12: 0 | G12: =sum(E12:F12) -> 0 | H12: =D12*G12 -> 0
C13: Karage Ala Carte | D13: =VLOOKUP(C13, 'LIST HPP'!$B$4:$C$39, 2, ) -> 14155 | E13: 0 | G13: =sum(E13:F13) -> 0 | H13: =D13*G13 -> 0
C14: Hot Honey Karage Ala Carte | D14: =VLOOKUP(C14, 'LIST HPP'!$B$4:$C$39, 2, ) -> 15435 | E14: 1 | G14: =sum(E14:F14) -> 1 | H14: =D14*G14 -> 15435
... C32: Gyuniku Bento | D32: =VLOOKUP(C32, 'LIST HPP'!$B$4:$C$39, 2, ) -> 14616.31 | E32: 0 | G32: =sum(E32:F32) -> 0 | H32: =D32*G32 -> 0
A33: GRAB/ OFFLINE Q | C33: Matcha Latte | D33: =VLOOKUP(C33, 'LIST HPP'!$B$4:$C$39, 2, ) -> 8805.63 | E33: 0 | G33: =SUM(E33:F33) -> 0 | H33: =D33*G33 -> 0 | I33: =sum(H33:H63) -> 557174.26 | J33: 1012498 | K33: =(J33-I33)/J33 -> 0.44970335 | L33: =J33-I33 -> 455323.74
C34: Hojicha Latte | D34: =VLOOKUP(C34, 'LIST HPP'!$B$4:$C$39, 2, ) -> 8150.63 | E34: 0 | G34: =SUM(E34:F34) -> 0 | H34: =D34*G34 -> 0
C35: Choco Latte | D35: =VLOOKUP(C35, 'LIST HPP'!$B$4:$C$39, 2, ) -> 6013.63 | E35: 0 | G35: =SUM(E35:F35) -> 0 | H35: =D35*G35 -> 0
C36: Choco Ichigo Latte | D36: =VLOOKUP(C36, 'LIST HPP'!$B$4:$C$39, 2, ) -> 7131.43 | E36: 0 | G36: =SUM(E36:F36) -> 0 | H36: =D36*G36 -> 0
C37: Matcha Tea | D37: =VLOOKUP(C37, 'LIST HPP'!$B$4:$C$39, 2, ) -> 3748.21 | E37: 0 | G37: =SUM(E37:F37) -> 0 | H37: =D37*G37 -> 0
C38: Ice Tea | D38: =VLOOKUP(C38, 'LIST HPP'!$B$4:$C$39, 2, ) -> 1448.63 | E38: 2 | G38: =SUM(E38:F38) -> 2 | H38: =D38*G38 -> 2897.26
C39: Gyumeshi | D39: =VLOOKUP(C39, 'LIST HPP'!$B$4:$C$39, 2, ) -> 11670 | E39: 7 | G39: =SUM(E39:F39) -> 7 | H39: =D39*G39 -> 81690
C40: Karage Don | D40: =VLOOKUP(C40, 'LIST HPP'!$B$4:$C$39, 2, ) -> 9350.16 | E40: 1 | G40: =SUM(E40:F40) -> 1 | H40: =D40*G40 -> 9350.16
C41: Hot Honey Karage Don | D41: =VLOOKUP(C41, 'LIST HPP'!$B$4:$C$39, 2, ) -> 9990.16 | E41: 6 | G41: =SUM(E41:F41) -> 6 | H41: =D41*G41 -> 59940.96
C42: Chicken Katsu Don | D42: =VLOOKUP(C42, 'LIST HPP'!$B$4:$C$39, 2, ) -> 7445.2 | E42: 18 | G42: =SUM(E42:F42) -> 18 | H42: =D42*G42 -> 134013.6
C43: Gyuniku Ala Carte | D43: =VLOOKUP(C43, 'LIST HPP'!$B$4:$C$39, 2, ) -> 17260 | E43: 1 | G43: =SUM(E43:F43) -> 1 | H43: =D43*G43 -> 17260
C44: Karage Ala Carte | D44: =VLOOKUP(C44, 'LIST HPP'!$B$4:$C$39, 2, ) -> 14155 | E44: 3 | G44: =SUM(E44:F44) -> 3 | H44: =D44*G44 -> 42465
C45: Hot Honey Karage Ala Carte | D45: =VLOOKUP(C45, 'LIST HPP'!$B$4:$C$39, 2, ) -> 15435 | E45: 3 | G45: =SUM(E45:F45) -> 3 | H45: =D45*G45 -> 46305
... C63: Gyuniku Bento | D63: =VLOOKUP(C63, 'LIST HPP'!$B$4:$C$39, 2, ) -> 14616.31 | E63: 0 | G63: =SUM(E63:F63) -> 0 | H63: =D63*G63 -> 0
A64: GOJEK | C64: Matcha Latte | D64: =VLOOKUP(C64, 'LIST HPP'!$B$4:$C$39, 2, ) -> 8805.63 | E64: 0 | G64: =Sum(E64:F64) -> 0 | H64: =D64*G64 -> 0 | I64: =sum(H64:H94) -> 37817.76 | J64: 61912 | K64: =(J64-I64)/J64 -> 0.38916914 | L64: =J64-I64 -> 24094.24
C65: Hojicha Latte | D65: =VLOOKUP(C65, 'LIST HPP'!$B$4:$C$39, 2, ) -> 8150.63 | E65: 0 | G65: =Sum(E65:F65) -> 0 | H65: =D65*G65 -> 0
C66: Choco Latte | D66: =VLOOKUP(C66, 'LIST HPP'!$B$4:$C$39, 2, ) -> 6013.63 | E66: 0 | G66: =Sum(E66:F66) -> 0 | H66: =D66*G66 -> 0
C67: Choco Ichigo Latte | D67: =VLOOKUP(C67, 'LIST HPP'!$B$4:$C$39, 2, ) -> 7131.43 | E67: 0 | G67: =Sum(E67:F67) -> 0 | H67: =D67*G67 -> 0
C68: Matcha Tea | D68: =VLOOKUP(C68, 'LIST HPP'!$B$4:$C$39, 2, ) -> 3748.21 | E68: 0 | G68: =Sum(E68:F68) -> 0 | H68: =D68*G68 -> 0
C69: Ice Tea | D69: =VLOOKUP(C69, 'LIST HPP'!$B$4:$C$39, 2, ) -> 1448.63 | E69: 0 | G69: =Sum(E69:F69) -> 0 | H69: =D69*G69 -> 0
C70: Gyumeshi | D70: =VLOOKUP(C70, 'LIST HPP'!$B$4:$C$39, 2, ) -> 11670 | E70: 0 | G70: =Sum(E70:F70) -> 0 | H70: =D70*G70 -> 0
C71: Karage Don | D71: =VLOOKUP(C71, 'LIST HPP'!$B$4:$C$39, 2, ) -> 9350.16 | E71: 0 | G71: =Sum(E71:F71) -> 0 | H71: =D71*G71 -> 0
C72: Hot Honey Karage Don | D72: =VLOOKUP(C72, 'LIST HPP'!$B$4:$C$39, 2, ) -> 9990.16 | E72: 0 | G72: =Sum(E72:F72) -> 0 | H72: =D72*G72 -> 0
C73: Chicken Katsu Don | D73: =VLOOKUP(C73, 'LIST HPP'!$B$4:$C$39, 2, ) -> 7445.2 | E73: 3 | G73: =Sum(E73:F73) -> 3 | H73: =D73*G73 -> 22335.6
C74: Gyuniku Ala Carte | D74: =VLOOKUP(C74, 'LIST HPP'!$B$4:$C$39, 2, ) -> 17260 | E74: 0 | G74: =Sum(E74:F74) -> 0 | H74: =D74*G74 -> 0
...

Sheet 21062026
A1: PLATFORM | B1: Tanggal | C1: Nama Item | D1: HPP | E1: Jumlah | F1: Jumlah QR | G1: Total Jumlah | H1: Total | I1: Total HPP | J1: Uang Masuk | K1: Margin | L1: Gross Profit
A2: SHOPEE | C2: Matcha Latte | D2: =VLOOKUP(C2, 'LIST HPP'!$B$4:$C$39, 2, ) -> 8805.63 | E2: 2 | G2: =sum(E2:F2) -> 2 | H2: =D2*G2 -> 17611.26 | I2: =sum(H2:H32) -> 708574.15 | J2: 1103513 | K2: =(J2-I2)/J2 -> 0.35789234 | L2: =J2-I2 -> 394938.85
C3: Hojicha Latte | D3: =VLOOKUP(C3, 'LIST HPP'!$B$4:$C$39, 2, ) -> 8150.63 | E3: 0 | G3: =sum(E3:F3) -> 0 | H3: =D3*G3 -> 0
C4: Choco Latte | D4: =VLOOKUP(C4, 'LIST HPP'!$B$4:$C$39, 2, ) -> 6013.63 | E4: 0 | G4: =sum(E4:F4) -> 0 | H4: =D4*G4 -> 0
C5: Choco Ichigo Latte | D5: =VLOOKUP(C5, 'LIST HPP'!$B$4:$C$39, 2, ) -> 7131.43 | E5: 0 | G5: =sum(E5:F5) -> 0 | H5: =D5*G5 -> 0
C6: Matcha Tea | D6: =VLOOKUP(C6, 'LIST HPP'!$B$4:$C$39, 2, ) -> 3748.21 | E6: 3 | G6: =sum(E6:F6) -> 3 | H6: =D6*G6 -> 11244.63
C7: Ice Tea | D7: =VLOOKUP(C7, 'LIST HPP'!$B$4:$C$39, 2, ) -> 1448.63 | E7: 2 | G7: =sum(E7:F7) -> 2 | H7: =D7*G7 -> 2897.26
C8: Gyumeshi | D8: =VLOOKUP(C8, 'LIST HPP'!$B$4:$C$39, 2, ) -> 11670 | E8: 5 | G8: =sum(E8:F8) -> 5 | H8: =D8*G8 -> 58350
C9: Karage Don | D9: =VLOOKUP(C9, 'LIST HPP'!$B$4:$C$39, 2, ) -> 9350.16 | E9: 14 | G9: =sum(E9:F9) -> 14 | H9: =D9*G9 -> 130902.24
C10: Hot Honey Karage Don | D10: =VLOOKUP(C10, 'LIST HPP'!$B$4:$C$39, 2, ) -> 9990.16 | E10: 2 | G10: =sum(E10:F10) -> 2 | H10: =D10*G10 -> 19980.32
C11: Chicken Katsu Don | D11: =VLOOKUP(C11, 'LIST HPP'!$B$4:$C$39, 2, ) -> 7445.2 | E11: 39 | G11: =sum(E11:F11) -> 39 | H11: =D11*G11 -> 290362.8
C12: Gyuniku Ala Carte | D12: =VLOOKUP(C12, 'LIST HPP'!$B$4:$C$39, 2, ) -> 17260 | E12: 0 | G12: =sum(E12:F12) -> 0 | H12: =D12*G12 -> 0
C13: Karage Ala Carte | D13: =VLOOKUP(C13, 'LIST HPP'!$B$4:$C$39, 2, ) -> 14155 | E13: 2 | G13: =sum(E13:F13) -> 2 | H13: =D13*G13 -> 28310
C14: Hot Honey Karage Ala Carte | D14: =VLOOKUP(C14, 'LIST HPP'!$B$4:$C$39, 2, ) -> 15435 | E14: 2 | G14: =sum(E14:F14) -> 2 | H14: =D14*G14 -> 30870
... C32: Gyuniku Bento | D32: =VLOOKUP(C32, 'LIST HPP'!$B$4:$C$39, 2, ) -> 14616.31 | E32: 0 | G32: =sum(E32:F32) -> 0 | H32: =D32*G32 -> 0
A33: GRAB/ OFFLINE Q | C33: Matcha Latte | D33: =VLOOKUP(C33, 'LIST HPP'!$B$4:$C$39, 2, ) -> 8805.63 | E33: 0 | F33: 1 | G33: =SUM(E33:F33) -> 1 | H33: =D33*G33 -> 8805.63 | I33: =sum(H33:H63) -> 593267.74 | J33: 1052812 | K33: =(J33-I33)/J33 -> 0.43649223 | L33: =J33-I33 -> 459544.26
C34: Hojicha Latte | D34: =VLOOKUP(C34, 'LIST HPP'!$B$4:$C$39, 2, ) -> 8150.63 | E34: 0 | F34: 0 | G34: =SUM(E34:F34) -> 0 | H34: =D34*G34 -> 0
C35: Choco Latte | D35: =VLOOKUP(C35, 'LIST HPP'!$B$4:$C$39, 2, ) -> 6013.63 | E35: 0 | F35: 0 | G35: =SUM(E35:F35) -> 0 | H35: =D35*G35 -> 0
C36: Choco Ichigo Latte | D36: =VLOOKUP(C36, 'LIST HPP'!$B$4:$C$39, 2, ) -> 7131.43 | E36: 0 | F36: 0 | G36: =SUM(E36:F36) -> 0 | H36: =D36*G36 -> 0
C37: Matcha Tea | D37: =VLOOKUP(C37, 'LIST HPP'!$B$4:$C$39, 2, ) -> 3748.21 | E37: 0 | F37: 0 | G37: =SUM(E37:F37) -> 0 | H37: =D37*G37 -> 0
C38: Ice Tea | D38: =VLOOKUP(C38, 'LIST HPP'!$B$4:$C$39, 2, ) -> 1448.63 | E38: 1 | F38: 0 | G38: =SUM(E38:F38) -> 1 | H38: =D38*G38 -> 1448.63
C39: Gyumeshi | D39: =VLOOKUP(C39, 'LIST HPP'!$B$4:$C$39, 2, ) -> 11670 | E39: 5 | F39: 0 | G39: =SUM(E39:F39) -> 5 | H39: =D39*G39 -> 58350
C40: Karage Don | D40: =VLOOKUP(C40, 'LIST HPP'!$B$4:$C$39, 2, ) -> 9350.16 | E40: 0 | F40: 0 | G40: =SUM(E40:F40) -> 0 | H40: =D40*G40 -> 0
C41: Hot Honey Karage Don | D41: =VLOOKUP(C41, 'LIST HPP'!$B$4:$C$39, 2, ) -> 9990.16 | E41: 1 | F41: 0 | G41: =SUM(E41:F41) -> 1 | H41: =D41*G41 -> 9990.16
C42: Chicken Katsu Don | D42: =VLOOKUP(C42, 'LIST HPP'!$B$4:$C$39, 2, ) -> 7445.2 | E42: 46 | F42: 0 | G42: =SUM(E42:F42) -> 46 | H42: =D42*G42 -> 342479.2
C43: Gyuniku Ala Carte | D43: =VLOOKUP(C43, 'LIST HPP'!$B$4:$C$39, 2, ) -> 17260 | E43: 0 | F43: 0 | G43: =SUM(E43:F43) -> 0 | H43: =D43*G43 -> 0
C44: Karage Ala Carte | D44: =VLOOKUP(C44, 'LIST HPP'!$B$4:$C$39, 2, ) -> 14155 | E44: 1 | F44: 0 | G44: =SUM(E44:F44) -> 1 | H44: =D44*G44 -> 14155
C45: Hot Honey Karage Ala Carte | D45: =VLOOKUP(C45, 'LIST HPP'!$B$4:$C$39, 2, ) -> 15435 | E45: 2 | F45: 0 | G45: =SUM(E45:F45) -> 2 | H45: =D45*G45 -> 30870
... C63: Gyuniku Bento | D63: =VLOOKUP(C63, 'LIST HPP'!$B$4:$C$39, 2, ) -> 14616.31 | E63: 0 | F63: 0 | G63: =SUM(E63:F63) -> 0 | H63: =D63*G63 -> 0
A64: GOJEK | C64: Matcha Latte | D64: =VLOOKUP(C64, 'LIST HPP'!$B$4:$C$39, 2, ) -> 8805.63 | E64: 1 | G64: =Sum(E64:F64) -> 1 | H64: =D64*G64 -> 8805.63 | I64: =sum(H64:H94) -> 32249.73 | J64: 62872 | K64: =(J64-I64)/J64 -> 0.48705735 | L64: =J64-I64 -> 30622.27
C65: Hojicha Latte | D65: =VLOOKUP(C65, 'LIST HPP'!$B$4:$C$39, 2, ) -> 8150.63 | E65: 0 | G65: =Sum(E65:F65) -> 0 | H65: =D65*G65 -> 0
C66: Choco Latte | D66: =VLOOKUP(C66, 'LIST HPP'!$B$4:$C$39, 2, ) -> 6013.63 | E66: 0 | G66: =Sum(E66:F66) -> 0 | H66: =D66*G66 -> 0
C67: Choco Ichigo Latte | D67: =VLOOKUP(C67, 'LIST HPP'!$B$4:$C$39, 2, ) -> 7131.43 | E67: 0 | G67: =Sum(E67:F67) -> 0 | H67: =D67*G67 -> 0
C68: Matcha Tea | D68: =VLOOKUP(C68, 'LIST HPP'!$B$4:$C$39, 2, ) -> 3748.21 | E68: 0 | G68: =Sum(E68:F68) -> 0 | H68: =D68*G68 -> 0
C69: Ice Tea | D69: =VLOOKUP(C69, 'LIST HPP'!$B$4:$C$39, 2, ) -> 1448.63 | E69: 0 | G69: =Sum(E69:F69) -> 0 | H69: =D69*G69 -> 0
C70: Gyumeshi | D70: =VLOOKUP(C70, 'LIST HPP'!$B$4:$C$39, 2, ) -> 11670 | E70: 0 | G70: =Sum(E70:F70) -> 0 | H70: =D70*G70 -> 0
C71: Karage Don | D71: =VLOOKUP(C71, 'LIST HPP'!$B$4:$C$39, 2, ) -> 9350.16 | E71: 0 | G71: =Sum(E71:F71) -> 0 | H71: =D71*G71 -> 0
C72: Hot Honey Karage Don | D72: =VLOOKUP(C72, 'LIST HPP'!$B$4:$C$39, 2, ) -> 9990.16 | E72: 0 | G72: =Sum(E72:F72) -> 0 | H72: =D72*G72 -> 0
C73: Chicken Katsu Don | D73: =VLOOKUP(C73, 'LIST HPP'!$B$4:$C$39, 2, ) -> 7445.2 | E73: 3 | G73: =Sum(E73:F73) -> 3 | H73: =D73*G73 -> 22335.6
C74: Gyuniku Ala Carte | D74: =VLOOKUP(C74, 'LIST HPP'!$B$4:$C$39, 2, ) -> 17260 | E74: 0 | G74: =Sum(E74:F74) -> 0 | H74: =D74*G74 -> 0
...

Sheet 20062026
A1: PLATFORM | B1: Tanggal | C1: Nama Item | D1: HPP | E1: Jumlah | F1: Jumlah QR | G1: Total Jumlah | H1: Total | I1: Total HPP | J1: Uang Masuk | K1: Margin | L1: Gross Profit
A2: SHOPEE | C2: Matcha Latte | D2: =VLOOKUP(C2, 'LIST HPP'!$B$4:$C$39, 2, ) -> 8805.63 | E2: 1 | G2: =sum(E2:F2) -> 1 | H2: =D2*G2 -> 8805.63 | I2: =sum(H2:H32) -> 374763.61 | J2: 547221 | K2: =(J2-I2)/J2 -> 0.31515126 | L2: =J2-I2 -> 172457.39
C3: Hojicha Latte | D3: =VLOOKUP(C3, 'LIST HPP'!$B$4:$C$39, 2, ) -> 8150.63 | E3: 0 | G3: =sum(E3:F3) -> 0 | H3: =D3*G3 -> 0
C4: Choco Latte | D4: =VLOOKUP(C4, 'LIST HPP'!$B$4:$C$39, 2, ) -> 6013.63 | E4: 0 | G4: =sum(E4:F4) -> 0 | H4: =D4*G4 -> 0
C5: Choco Ichigo Latte | D5: =VLOOKUP(C5, 'LIST HPP'!$B$4:$C$39, 2, ) -> 7131.43 | E5: 0 | G5: =sum(E5:F5) -> 0 | H5: =D5*G5 -> 0
C6: Matcha Tea | D6: =VLOOKUP(C6, 'LIST HPP'!$B$4:$C$39, 2, ) -> 3748.21 | E6: 1 | G6: =sum(E6:F6) -> 1 | H6: =D6*G6 -> 3748.21
C7: Ice Tea | D7: =VLOOKUP(C7, 'LIST HPP'!$B$4:$C$39, 2, ) -> 1448.63 | E7: 2 | G7: =sum(E7:F7) -> 2 | H7: =D7*G7 -> 2897.26
C8: Gyumeshi | D8: =VLOOKUP(C8, 'LIST HPP'!$B$4:$C$39, 2, ) -> 11670 | E8: 3 | G8: =sum(E8:F8) -> 3 | H8: =D8*G8 -> 35010
C9: Karage Don | D9: =VLOOKUP(C9, 'LIST HPP'!$B$4:$C$39, 2, ) -> 9350.16 | E9: 7 | G9: =sum(E9:F9) -> 7 | H9: =D9*G9 -> 65451.12
C10: Hot Honey Karage Don | D10: =VLOOKUP(C10, 'LIST HPP'!$B$4:$C$39, 2, ) -> 9990.16 | E10: 3 | G10: =sum(E10:F10) -> 3 | H10: =D10*G10 -> 29970.48
C11: Chicken Katsu Don | D11: =VLOOKUP(C11, 'LIST HPP'!$B$4:$C$39, 2, ) -> 7445.2 | E11: 23 | G11: =sum(E11:F11) -> 23 | H11: =D11*G11 -> 171239.6
C12: Gyuniku Ala Carte | D12: =VLOOKUP(C12, 'LIST HPP'!$B$4:$C$39, 2, ) -> 17260 | E12: 0 | G12: =sum(E12:F12) -> 0 | H12: =D12*G12 -> 0
C13: Karage Ala Carte | D13: =VLOOKUP(C13, 'LIST HPP'!$B$4:$C$39, 2, ) -> 14155 | E13: 0 | G13: =sum(E13:F13) -> 0 | H13: =D13*G13 -> 0
C14: Hot Honey Karage Ala Carte | D14: =VLOOKUP(C14, 'LIST HPP'!$B$4:$C$39, 2, ) -> 15435 | E14: 0 | G14: =sum(E14:F14) -> 0 | H14: =D14*G14 -> 0
... C32: Gyuniku Bento | D32: =VLOOKUP(C32, 'LIST HPP'!$B$4:$C$39, 2, ) -> 14616.31 | E32: 0 | G32: =sum(E32:F32) -> 0 | H32: =D32*G32 -> 0
A33: GRAB/ OFFLINE Q | C33: Matcha Latte | D33: =VLOOKUP(C33, 'LIST HPP'!$B$4:$C$39, 2, ) -> 8805.63 | E33: 1 | G33: =SUM(E33:F33) -> 1 | H33: =D33*G33 -> 8805.63 | I33: =sum(H33:H63) -> 321010.49 | J33: 538745 | K33: =(J33-I33)/J33 -> 0.40415133 | L33: =J33-I33 -> 217734.51
C34: Hojicha Latte | D34: =VLOOKUP(C34, 'LIST HPP'!$B$4:$C$39, 2, ) -> 8150.63 | E34: 0 | G34: =SUM(E34:F34) -> 0 | H34: =D34*G34 -> 0
C35: Choco Latte | D35: =VLOOKUP(C35, 'LIST HPP'!$B$4:$C$39, 2, ) -> 6013.63 | E35: 0 | G35: =SUM(E35:F35) -> 0 | H35: =D35*G35 -> 0
C36: Choco Ichigo Latte | D36: =VLOOKUP(C36, 'LIST HPP'!$B$4:$C$39, 2, ) -> 7131.43 | E36: 0 | G36: =SUM(E36:F36) -> 0 | H36: =D36*G36 -> 0
C37: Matcha Tea | D37: =VLOOKUP(C37, 'LIST HPP'!$B$4:$C$39, 2, ) -> 3748.21 | E37: 2 | G37: =SUM(E37:F37) -> 2 | H37: =D37*G37 -> 7496.42
C38: Ice Tea | D38: =VLOOKUP(C38, 'LIST HPP'!$B$4:$C$39, 2, ) -> 1448.63 | E38: 1 | G38: =SUM(E38:F38) -> 1 | H38: =D38*G38 -> 1448.63
C39: Gyumeshi | D39: =VLOOKUP(C39, 'LIST HPP'!$B$4:$C$39, 2, ) -> 11670 | E39: 6 | G39: =SUM(E39:F39) -> 6 | H39: =D39*G39 -> 70020
C40: Karage Don | D40: =VLOOKUP(C40, 'LIST HPP'!$B$4:$C$39, 2, ) -> 9350.16 | E40: 1 | G40: =SUM(E40:F40) -> 1 | H40: =D40*G40 -> 9350.16
C41: Hot Honey Karage Don | D41: =VLOOKUP(C41, 'LIST HPP'!$B$4:$C$39, 2, ) -> 9990.16 | E41: 1 | G41: =SUM(E41:F41) -> 1 | H41: =D41*G41 -> 9990.16
C42: Chicken Katsu Don | D42: =VLOOKUP(C42, 'LIST HPP'!$B$4:$C$39, 2, ) -> 7445.2 | E42: 10 | G42: =SUM(E42:F42) -> 10 | H42: =D42*G42 -> 74452
C43: Gyuniku Ala Carte | D43: =VLOOKUP(C43, 'LIST HPP'!$B$4:$C$39, 2, ) -> 17260 | E43: 0 | G43: =SUM(E43:F43) -> 0 | H43: =D43*G43 -> 0
C44: Karage Ala Carte | D44: =VLOOKUP(C44, 'LIST HPP'!$B$4:$C$39, 2, ) -> 14155 | E44: 0 | G44: =SUM(E44:F44) -> 0 | H44: =D44*G44 -> 0
C45: Hot Honey Karage Ala Carte | D45: =VLOOKUP(C45, 'LIST HPP'!$B$4:$C$39, 2, ) -> 15435 | E45: 0 | G45: =SUM(E45:F45) -> 0 | H45: =D45*G45 -> 0
... C63: Gyuniku Bento | D63: =VLOOKUP(C63, 'LIST HPP'!$B$4:$C$39, 2, ) -> 14616.31 | E63: 1 | G63: =SUM(E63:F63) -> 1 | H63: =D63*G63 -> 14616.31
A64: GOJEK | C64: Matcha Latte | D64: =VLOOKUP(C64, 'LIST HPP'!$B$4:$C$39, 2, ) -> 8805.63 | E64: 0 | G64: =Sum(E64:F64) -> 0 | H64: =D64*G64 -> 0 | I64: =sum(H64:H94) -> 41271.31 | J64: 74682 | K64: =(J64-I64)/J64 -> 0.44737273 | L64: =J64-I64 -> 33410.69
C65: Hojicha Latte | D65: =VLOOKUP(C65, 'LIST HPP'!$B$4:$C$39, 2, ) -> 8150.63 | E65: 0 | G65: =Sum(E65:F65) -> 0 | H65: =D65*G65 -> 0
C66: Choco Latte | D66: =VLOOKUP(C66, 'LIST HPP'!$B$4:$C$39, 2, ) -> 6013.63 | E66: 0 | G66: =Sum(E66:F66) -> 0 | H66: =D66*G66 -> 0
C67: Choco Ichigo Latte | D67: =VLOOKUP(C67, 'LIST HPP'!$B$4:$C$39, 2, ) -> 7131.43 | E67: 0 | G67: =Sum(E67:F67) -> 0 | H67: =D67*G67 -> 0
C68: Matcha Tea | D68: =VLOOKUP(C68, 'LIST HPP'!$B$4:$C$39, 2, ) -> 3748.21 | E68: 1 | G68: =Sum(E68:F68) -> 1 | H68: =D68*G68 -> 3748.21
C69: Ice Tea | D69: =VLOOKUP(C69, 'LIST HPP'!$B$4:$C$39, 2, ) -> 1448.63 | E69: 0 | G69: =Sum(E69:F69) -> 0 | H69: =D69*G69 -> 0
C70: Gyumeshi | D70: =VLOOKUP(C70, 'LIST HPP'!$B$4:$C$39, 2, ) -> 11670 | E70: 0 | G70: =Sum(E70:F70) -> 0 | H70: =D70*G70 -> 0
C71: Karage Don | D71: =VLOOKUP(C71, 'LIST HPP'!$B$4:$C$39, 2, ) -> 9350.16 | E71: 0 | G71: =Sum(E71:F71) -> 0 | H71: =D71*G71 -> 0
C72: Hot Honey Karage Don | D72: =VLOOKUP(C72, 'LIST HPP'!$B$4:$C$39, 2, ) -> 9990.16 | E72: 0 | G72: =Sum(E72:F72) -> 0 | H72: =D72*G72 -> 0
C73: Chicken Katsu Don | D73: =VLOOKUP(C73, 'LIST HPP'!$B$4:$C$39, 2, ) -> 7445.2 | E73: 3 | G73: =Sum(E73:F73) -> 3 | H73: =D73*G73 -> 22335.6
C74: Gyuniku Ala Carte | D74: =VLOOKUP(C74, 'LIST HPP'!$B$4:$C$39, 2, ) -> 17260 | E74: 0 | G74: =Sum(E74:F74) -> 0 | H74: =D74*G74 -> 0
...

Sheet 19062026
A1: PLATFORM | B1: Tanggal | C1: Nama Item | D1: HPP | E1: Jumlah | F1: Jumlah QR | G1: Total Jumlah | H1: Total | I1: Total HPP | J1: Uang Masuk | K1: Margin | L1: Gross Profit
A2: SHOPEE | C2: Matcha Latte | D2: =VLOOKUP(C2, 'LIST HPP'!$B$4:$C$39, 2, ) -> 8805.63 | E2: 0 | G2: =sum(E2:F2) -> 0 | H2: =D2*G2 -> 0 | I2: =sum(H2:H32) -> 573511.46 | J2: 921835 | K2: =(J2-I2)/J2 -> 0.37785888 | L2: =J2-I2 -> 348323.54
C3: Hojicha Latte | D3: =VLOOKUP(C3, 'LIST HPP'!$B$4:$C$39, 2, ) -> 8150.63 | E3: 0 | G3: =sum(E3:F3) -> 0 | H3: =D3*G3 -> 0
C4: Choco Latte | D4: =VLOOKUP(C4, 'LIST HPP'!$B$4:$C$39, 2, ) -> 6013.63 | E4: 1 | G4: =sum(E4:F4) -> 1 | H4: =D4*G4 -> 6013.63
C5: Choco Ichigo Latte | D5: =VLOOKUP(C5, 'LIST HPP'!$B$4:$C$39, 2, ) -> 7131.43 | E5: 0 | G5: =sum(E5:F5) -> 0 | H5: =D5*G5 -> 0
C6: Matcha Tea | D6: =VLOOKUP(C6, 'LIST HPP'!$B$4:$C$39, 2, ) -> 3748.21 | E6: 2 | G6: =sum(E6:F6) -> 2 | H6: =D6*G6 -> 7496.42
C7: Ice Tea | D7: =VLOOKUP(C7, 'LIST HPP'!$B$4:$C$39, 2, ) -> 1448.63 | E7: 2 | G7: =sum(E7:F7) -> 2 | H7: =D7*G7 -> 2897.26
C8: Gyumeshi | D8: =VLOOKUP(C8, 'LIST HPP'!$B$4:$C$39, 2, ) -> 11670 | E8: 5 | G8: =sum(E8:F8) -> 5 | H8: =D8*G8 -> 58350
C9: Karage Don | D9: =VLOOKUP(C9, 'LIST HPP'!$B$4:$C$39, 2, ) -> 9350.16 | E9: 18 | G9: =sum(E9:F9) -> 18 | H9: =D9*G9 -> 168302.88
C10: Hot Honey Karage Don | D10: =VLOOKUP(C10, 'LIST HPP'!$B$4:$C$39, 2, ) -> 9990.16 | E10: 3 | G10: =sum(E10:F10) -> 3 | H10: =D10*G10 -> 29970.48
C11: Chicken Katsu Don | D11: =VLOOKUP(C11, 'LIST HPP'!$B$4:$C$39, 2, ) -> 7445.2 | E11: 22 | G11: =sum(E11:F11) -> 22 | H11: =D11*G11 -> 163794.4
C12: Gyuniku Ala Carte | D12: =VLOOKUP(C12, 'LIST HPP'!$B$4:$C$39, 2, ) -> 17260 | E12: 0 | G12: =sum(E12:F12) -> 0 | H12: =D12*G12 -> 0
C13: Karage Ala Carte | D13: =VLOOKUP(C13, 'LIST HPP'!$B$4:$C$39, 2, ) -> 14155 | E13: 0 | G13: =sum(E13:F13) -> 0 | H13: =D13*G13 -> 0
C14: Hot Honey Karage Ala Carte | D14: =VLOOKUP(C14, 'LIST HPP'!$B$4:$C$39, 2, ) -> 15435 | E14: 0 | G14: =sum(E14:F14) -> 0 | H14: =D14*G14 -> 0
... C32: Gyuniku Bento | D32: =VLOOKUP(C32, 'LIST HPP'!$B$4:$C$39, 2, ) -> 14616.31 | E32: 0 | G32: =sum(E32:F32) -> 0 | H32: =D32*G32 -> 0
A33: GRAB/ OFFLINE Q | C33: Matcha Latte | D33: =VLOOKUP(C33, 'LIST HPP'!$B$4:$C$39, 2, ) -> 8805.63 | E33: 0 | G33: =SUM(E33:F33) -> 0 | H33: =D33*G33 -> 0 | I33: =sum(H33:H63) -> 152894.17 | J33: 100180 | K33: =(J33-I33)/J33 -> -0.52619455 | L33: =J33-I33 -> -52714.17
C34: Hojicha Latte | D34: =VLOOKUP(C34, 'LIST HPP'!$B$4:$C$39, 2, ) -> 8150.63 | E34: 0 | G34: =SUM(E34:F34) -> 0 | H34: =D34*G34 -> 0
C35: Choco Latte | D35: =VLOOKUP(C35, 'LIST HPP'!$B$4:$C$39, 2, ) -> 6013.63 | E35: 0 | G35: =SUM(E35:F35) -> 0 | H35: =D35*G35 -> 0
C36: Choco Ichigo Latte | D36: =VLOOKUP(C36, 'LIST HPP'!$B$4:$C$39, 2, ) -> 7131.43 | E36: 0 | G36: =SUM(E36:F36) -> 0 | H36: =D36*G36 -> 0
C37: Matcha Tea | D37: =VLOOKUP(C37, 'LIST HPP'!$B$4:$C$39, 2, ) -> 3748.21 | E37: 2 | G37: =SUM(E37:F37) -> 2 | H37: =D37*G37 -> 7496.42
C38: Ice Tea | D38: =VLOOKUP(C38, 'LIST HPP'!$B$4:$C$39, 2, ) -> 1448.63 | E38: 0 | G38: =SUM(E38:F38) -> 0 | H38: =D38*G38 -> 0
C39: Gyumeshi | D39: =VLOOKUP(C39, 'LIST HPP'!$B$4:$C$39, 2, ) -> 11670 | E39: 1 | G39: =SUM(E39:F39) -> 1 | H39: =D39*G39 -> 11670
C40: Karage Don | D40: =VLOOKUP(C40, 'LIST HPP'!$B$4:$C$39, 2, ) -> 9350.16 | E40: 0 | G40: =SUM(E40:F40) -> 0 | H40: =D40*G40 -> 0
C41: Hot Honey Karage Don | D41: =VLOOKUP(C41, 'LIST HPP'!$B$4:$C$39, 2, ) -> 9990.16 | E41: 0 | G41: =SUM(E41:F41) -> 0 | H41: =D41*G41 -> 0
C42: Chicken Katsu Don | D42: =VLOOKUP(C42, 'LIST HPP'!$B$4:$C$39, 2, ) -> 7445.2 | E42: 10 | G42: =SUM(E42:F42) -> 10 | H42: =D42*G42 -> 74452
C43: Gyuniku Ala Carte | D43: =VLOOKUP(C43, 'LIST HPP'!$B$4:$C$39, 2, ) -> 17260 | E43: 0 | G43: =SUM(E43:F43) -> 0 | H43: =D43*G43 -> 0
C44: Karage Ala Carte | D44: =VLOOKUP(C44, 'LIST HPP'!$B$4:$C$39, 2, ) -> 14155 | E44: 0 | G44: =SUM(E44:F44) -> 0 | H44: =D44*G44 -> 0
C45: Hot Honey Karage Ala Carte | D45: =VLOOKUP(C45, 'LIST HPP'!$B$4:$C$39, 2, ) -> 15435 | E45: 0 | G45: =SUM(E45:F45) -> 0 | H45: =D45*G45 -> 0
... C63: Gyuniku Bento | D63: =VLOOKUP(C63, 'LIST HPP'!$B$4:$C$39, 2, ) -> 14616.31 | E63: 0 | G63: =SUM(E63:F63) -> 0 | H63: =D63*G63 -> 0
A64: GOJEK | C64: Matcha Latte | D64: =VLOOKUP(C64, 'LIST HPP'!$B$4:$C$39, 2, ) -> 8805.63 | E64: 0 | G64: =Sum(E64:F64) -> 0 | H64: =D64*G64 -> 0 | I64: =sum(H64:H94) -> 39201.62 | J64: 87717 | K64: =(J64-I64)/J64 -> 0.55308982 | L64: =J64-I64 -> 48515.38
C65: Hojicha Latte | D65: =VLOOKUP(C65, 'LIST HPP'!$B$4:$C$39, 2, ) -> 8150.63 | E65: 0 | G65: =Sum(E65:F65) -> 0 | H65: =D65*G65 -> 0
C66: Choco Latte | D66: =VLOOKUP(C66, 'LIST HPP'!$B$4:$C$39, 2, ) -> 6013.63 | E66: 1 | G66: =Sum(E66:F66) -> 1 | H66: =D66*G66 -> 6013.63
C67: Choco Ichigo Latte | D67: =VLOOKUP(C67, 'LIST HPP'!$B$4:$C$39, 2, ) -> 7131.43 | E67: 0 | G67: =Sum(E67:F67) -> 0 | H67: =D67*G67 -> 0
C68: Matcha Tea | D68: =VLOOKUP(C68, 'LIST HPP'!$B$4:$C$39, 2, ) -> 3748.21 | E68: 0 | G68: =Sum(E68:F68) -> 0 | H68: =D68*G68 -> 0
C69: Ice Tea | D69: =VLOOKUP(C69, 'LIST HPP'!$B$4:$C$39, 2, ) -> 1448.63 | E69: 1 | G69: =Sum(E69:F69) -> 1 | H69: =D69*G69 -> 1448.63
C70: Gyumeshi | D70: =VLOOKUP(C70, 'LIST HPP'!$B$4:$C$39, 2, ) -> 11670 | E70: 0 | G70: =Sum(E70:F70) -> 0 | H70: =D70*G70 -> 0
C71: Karage Don | D71: =VLOOKUP(C71, 'LIST HPP'!$B$4:$C$39, 2, ) -> 9350.16 | E71: 0 | G71: =Sum(E71:F71) -> 0 | H71: =D71*G71 -> 0
C72: Hot Honey Karage Don | D72: =VLOOKUP(C72, 'LIST HPP'!$B$4:$C$39, 2, ) -> 9990.16 | E72: 0 | G72: =Sum(E72:F72) -> 0 | H72: =D72*G72 -> 0
C73: Chicken Katsu Don | D73: =VLOOKUP(C73, 'LIST HPP'!$B$4:$C$39, 2, ) -> 7445.2 | E73: 1 | G73: =Sum(E73:F73) -> 1 | H73: =D73*G73 -> 7445.2
C74: Gyuniku Ala Carte | D74: =VLOOKUP(C74, 'LIST HPP'!$B$4:$C$39, 2, ) -> 17260 | E74: 0 | G74: =Sum(E74:F74) -> 0 | H74: =D74*G74 -> 0
...

Sheet 18062026
A1: PLATFORM | B1: Tanggal | C1: Nama Item | D1: HPP | E1: Jumlah | F1: Jumlah QR | G1: Total Jumlah | H1: Total | I1: Total HPP | J1: Uang Masuk | K1: Margin | L1: Gross Profit
A2: SHOPEE | C2: Matcha Latte | D2: =VLOOKUP(C2, 'LIST HPP'!$B$4:$C$39, 2, ) -> 8805.63 | E2: 0 | G2: =sum(E2:F2) -> 0 | H2: =D2*G2 -> 0 | I2: =sum(H2:H32) -> 652454.72 | J2: 1072185 | K2: =(J2-I2)/J2 -> 0.39147188 | L2: =J2-I2 -> 419730.28
C3: Hojicha Latte | D3: =VLOOKUP(C3, 'LIST HPP'!$B$4:$C$39, 2, ) -> 8150.63 | E3: 0 | G3: =sum(E3:F3) -> 0 | H3: =D3*G3 -> 0
C4: Choco Latte | D4: =VLOOKUP(C4, 'LIST HPP'!$B$4:$C$39, 2, ) -> 6013.63 | E4: 1 | G4: =sum(E4:F4) -> 1 | H4: =D4*G4 -> 6013.63
C5: Choco Ichigo Latte | D5: =VLOOKUP(C5, 'LIST HPP'!$B$4:$C$39, 2, ) -> 7131.43 | E5: 0 | G5: =sum(E5:F5) -> 0 | H5: =D5*G5 -> 0
C6: Matcha Tea | D6: =VLOOKUP(C6, 'LIST HPP'!$B$4:$C$39, 2, ) -> 3748.21 | E6: 0 | G6: =sum(E6:F6) -> 0 | H6: =D6*G6 -> 0
C7: Ice Tea | D7: =VLOOKUP(C7, 'LIST HPP'!$B$4:$C$39, 2, ) -> 1448.63 | E7: 4 | G7: =sum(E7:F7) -> 4 | H7: =D7*G7 -> 5794.52
C8: Gyumeshi | D8: =VLOOKUP(C8, 'LIST HPP'!$B$4:$C$39, 2, ) -> 11670 | E8: 8 | G8: =sum(E8:F8) -> 8 | H8: =D8*G8 -> 93360
C9: Karage Don | D9: =VLOOKUP(C9, 'LIST HPP'!$B$4:$C$39, 2, ) -> 9350.16 | E9: 6 | G9: =sum(E9:F9) -> 6 | H9: =D9*G9 -> 56100.96
C10: Hot Honey Karage Don | D10: =VLOOKUP(C10, 'LIST HPP'!$B$4:$C$39, 2, ) -> 9990.16 | E10: 7 | G10: =sum(E10:F10) -> 7 | H10: =D10*G10 -> 69931.12
C11: Chicken Katsu Don | D11: =VLOOKUP(C11, 'LIST HPP'!$B$4:$C$39, 2, ) -> 7445.2 | E11: 30 | G11: =sum(E11:F11) -> 30 | H11: =D11*G11 -> 223356
C12: Gyuniku Ala Carte | D12: =VLOOKUP(C12, 'LIST HPP'!$B$4:$C$39, 2, ) -> 17260 | E12: 0 | G12: =sum(E12:F12) -> 0 | H12: =D12*G12 -> 0
C13: Karage Ala Carte | D13: =VLOOKUP(C13, 'LIST HPP'!$B$4:$C$39, 2, ) -> 14155 | E13: 0 | G13: =sum(E13:F13) -> 0 | H13: =D13*G13 -> 0
C14: Hot Honey Karage Ala Carte | D14: =VLOOKUP(C14, 'LIST HPP'!$B$4:$C$39, 2, ) -> 15435 | E14: 0 | G14: =sum(E14:F14) -> 0 | H14: =D14*G14 -> 0
... C32: Gyuniku Bento | D32: =VLOOKUP(C32, 'LIST HPP'!$B$4:$C$39, 2, ) -> 14616.31 | E32: 2 | G32: =sum(E32:F32) -> 2 | H32: =D32*G32 -> 29232.62
A33: GRAB/ OFFLINE Q | C33: Matcha Latte | D33: =VLOOKUP(C33, 'LIST HPP'!$B$4:$C$39, 2, ) -> 8805.63 | E33: 0 | G33: =SUM(E33:F33) -> 0 | H33: =D33*G33 -> 0 | I33: =sum(H33:H63) -> 264708.89 | J33: 547574 | K33: =(J33-I33)/J33 -> 0.51657878 | L33: =J33-I33 -> 282865.11
C34: Hojicha Latte | D34: =VLOOKUP(C34, 'LIST HPP'!$B$4:$C$39, 2, ) -> 8150.63 | E34: 0 | G34: =SUM(E34:F34) -> 0 | H34: =D34*G34 -> 0
C35: Choco Latte | D35: =VLOOKUP(C35, 'LIST HPP'!$B$4:$C$39, 2, ) -> 6013.63 | E35: 1 | G35: =SUM(E35:F35) -> 1 | H35: =D35*G35 -> 6013.63
C36: Choco Ichigo Latte | D36: =VLOOKUP(C36, 'LIST HPP'!$B$4:$C$39, 2, ) -> 7131.43 | E36: 1 | G36: =SUM(E36:F36) -> 1 | H36: =D36*G36 -> 7131.43
C37: Matcha Tea | D37: =VLOOKUP(C37, 'LIST HPP'!$B$4:$C$39, 2, ) -> 3748.21 | E37: 0 | G37: =SUM(E37:F37) -> 0 | H37: =D37*G37 -> 0
C38: Ice Tea | D38: =VLOOKUP(C38, 'LIST HPP'!$B$4:$C$39, 2, ) -> 1448.63 | E38: 2 | G38: =SUM(E38:F38) -> 2 | H38: =D38*G38 -> 2897.26
C39: Gyumeshi | D39: =VLOOKUP(C39, 'LIST HPP'!$B$4:$C$39, 2, ) -> 11670 | E39: 1 | G39: =SUM(E39:F39) -> 1 | H39: =D39*G39 -> 11670
C40: Karage Don | D40: =VLOOKUP(C40, 'LIST HPP'!$B$4:$C$39, 2, ) -> 9350.16 | E40: 0 | G40: =SUM(E40:F40) -> 0 | H40: =D40*G40 -> 0
C41: Hot Honey Karage Don | D41: =VLOOKUP(C41, 'LIST HPP'!$B$4:$C$39, 2, ) -> 9990.16 | E41: 1 | G41: =SUM(E41:F41) -> 1 | H41: =D41*G41 -> 9990.16
C42: Chicken Katsu Don | D42: =VLOOKUP(C42, 'LIST HPP'!$B$4:$C$39, 2, ) -> 7445.2 | E42: 15 | G42: =SUM(E42:F42) -> 15 | H42: =D42*G42 -> 111678
C43: Gyuniku Ala Carte | D43: =VLOOKUP(C43, 'LIST HPP'!$B$4:$C$39, 2, ) -> 17260 | E43: 1 | G43: =SUM(E43:F43) -> 1 | H43: =D43*G43 -> 17260
C44: Karage Ala Carte | D44: =VLOOKUP(C44, 'LIST HPP'!$B$4:$C$39, 2, ) -> 14155 | E44: 1 | G44: =SUM(E44:F44) -> 1 | H44: =D44*G44 -> 14155
C45: Hot Honey Karage Ala Carte | D45: =VLOOKUP(C45, 'LIST HPP'!$B$4:$C$39, 2, ) -> 15435 | E45: 0 | G45: =SUM(E45:F45) -> 0 | H45: =D45*G45 -> 0
... C63: Gyuniku Bento | D63: =VLOOKUP(C63, 'LIST HPP'!$B$4:$C$39, 2, ) -> 14616.31 | E63: 0 | G63: =SUM(E63:F63) -> 0 | H63: =D63*G63 -> 0
A64: GOJEK | C64: Matcha Latte | D64: =VLOOKUP(C64, 'LIST HPP'!$B$4:$C$39, 2, ) -> 8805.63 | G64: =Sum(E64:F64) -> 0 | H64: =D64*G64 -> 0 | I64: =sum(H64:H94) -> 0 | K64: =(J64-I64)/J64 -> #DIV/0! | L64: =J64-I64 -> 0
C65: Hojicha Latte | D65: =VLOOKUP(C65, 'LIST HPP'!$B$4:$C$39, 2, ) -> 8150.63 | G65: =Sum(E65:F65) -> 0 | H65: =D65*G65 -> 0
C66: Choco Latte | D66: =VLOOKUP(C66, 'LIST HPP'!$B$4:$C$39, 2, ) -> 6013.63 | G66: =Sum(E66:F66) -> 0 | H66: =D66*G66 -> 0
C67: Choco Ichigo Latte | D67: =VLOOKUP(C67, 'LIST HPP'!$B$4:$C$39, 2, ) -> 7131.43 | G67: =Sum(E67:F67) -> 0 | H67: =D67*G67 -> 0
C68: Matcha Tea | D68: =VLOOKUP(C68, 'LIST HPP'!$B$4:$C$39, 2, ) -> 3748.21 | G68: =Sum(E68:F68) -> 0 | H68: =D68*G68 -> 0
C69: Ice Tea | D69: =VLOOKUP(C69, 'LIST HPP'!$B$4:$C$39, 2, ) -> 1448.63 | G69: =Sum(E69:F69) -> 0 | H69: =D69*G69 -> 0
C70: Gyumeshi | D70: =VLOOKUP(C70, 'LIST HPP'!$B$4:$C$39, 2, ) -> 11670 | G70: =Sum(E70:F70) -> 0 | H70: =D70*G70 -> 0
C71: Karage Don | D71: =VLOOKUP(C71, 'LIST HPP'!$B$4:$C$39, 2, ) -> 9350.16 | G71: =Sum(E71:F71) -> 0 | H71: =D71*G71 -> 0
C72: Hot Honey Karage Don | D72: =VLOOKUP(C72, 'LIST HPP'!$B$4:$C$39, 2, ) -> 9990.16 | G72: =Sum(E72:F72) -> 0 | H72: =D72*G72 -> 0
C73: Chicken Katsu Don | D73: =VLOOKUP(C73, 'LIST HPP'!$B$4:$C$39, 2, ) -> 7445.2 | G73: =Sum(E73:F73) -> 0 | H73: =D73*G73 -> 0
C74: Gyuniku Ala Carte | D74: =VLOOKUP(C74, 'LIST HPP'!$B$4:$C$39, 2, ) -> 17260 | G74: =Sum(E74:F74) -> 0 | H74: =D74*G74 -> 0
...

Sheet 17062026
A1: PLATFORM | B1: Tanggal | C1: Nama Item | D1: HPP | E1: Jumlah | F1: Jumlah QR | G1: Total Jumlah | H1: Total | I1: Total HPP | J1: Uang Masuk | K1: Margin | L1: Gross Profit
A2: SHOPEE | C2: Matcha Latte | D2: =VLOOKUP(C2, 'LIST HPP'!$B$4:$C$39, 2, ) -> 8805.63 | E2: 0 | G2: =sum(E2:F2) -> 0 | H2: =D2*G2 -> 0 | I2: =sum(H2:H32) -> 569976.63 | J2: 907481 | K2: =(J2-I2)/J2 -> 0.37191343 | L2: =J2-I2 -> 337504.37
C3: Hojicha Latte | D3: =VLOOKUP(C3, 'LIST HPP'!$B$4:$C$39, 2, ) -> 8150.63 | E3: 0 | G3: =sum(E3:F3) -> 0 | H3: =D3*G3 -> 0
C4: Choco Latte | D4: =VLOOKUP(C4, 'LIST HPP'!$B$4:$C$39, 2, ) -> 6013.63 | E4: 0 | G4: =sum(E4:F4) -> 0 | H4: =D4*G4 -> 0
C5: Choco Ichigo Latte | D5: =VLOOKUP(C5, 'LIST HPP'!$B$4:$C$39, 2, ) -> 7131.43 | E5: 0 | G5: =sum(E5:F5) -> 0 | H5: =D5*G5 -> 0
C6: Matcha Tea | D6: =VLOOKUP(C6, 'LIST HPP'!$B$4:$C$39, 2, ) -> 3748.21 | E6: 2 | G6: =sum(E6:F6) -> 2 | H6: =D6*G6 -> 7496.42
C7: Ice Tea | D7: =VLOOKUP(C7, 'LIST HPP'!$B$4:$C$39, 2, ) -> 1448.63 | E7: 7 | G7: =sum(E7:F7) -> 7 | H7: =D7*G7 -> 10140.41
C8: Gyumeshi | D8: =VLOOKUP(C8, 'LIST HPP'!$B$4:$C$39, 2, ) -> 11670 | E8: 3 | G8: =sum(E8:F8) -> 3 | H8: =D8*G8 -> 35010
C9: Karage Don | D9: =VLOOKUP(C9, 'LIST HPP'!$B$4:$C$39, 2, ) -> 9350.16 | E9: 4 | G9: =sum(E9:F9) -> 4 | H9: =D9*G9 -> 37400.64
C10: Hot Honey Karage Don | D10: =VLOOKUP(C10, 'LIST HPP'!$B$4:$C$39, 2, ) -> 9990.16 | E10: 3 | G10: =sum(E10:F10) -> 3 | H10: =D10*G10 -> 29970.48
C11: Chicken Katsu Don | D11: =VLOOKUP(C11, 'LIST HPP'!$B$4:$C$39, 2, ) -> 7445.2 | E11: 27 | G11: =sum(E11:F11) -> 27 | H11: =D11*G11 -> 201020.4
C12: Gyuniku Ala Carte | D12: =VLOOKUP(C12, 'LIST HPP'!$B$4:$C$39, 2, ) -> 17260 | E12: 0 | G12: =sum(E12:F12) -> 0 | H12: =D12*G12 -> 0
C13: Karage Ala Carte | D13: =VLOOKUP(C13, 'LIST HPP'!$B$4:$C$39, 2, ) -> 14155 | E13: 0 | G13: =sum(E13:F13) -> 0 | H13: =D13*G13 -> 0
C14: Hot Honey Karage Ala Carte | D14: =VLOOKUP(C14, 'LIST HPP'!$B$4:$C$39, 2, ) -> 15435 | E14: 0 | G14: =sum(E14:F14) -> 0 | H14: =D14*G14 -> 0
... C32: Gyuniku Bento | D32: =VLOOKUP(C32, 'LIST HPP'!$B$4:$C$39, 2, ) -> 14616.31 | E32: 0 | G32: =sum(E32:F32) -> 0 | H32: =D32*G32 -> 0
A33: GRAB/ OFFLINE Q | C33: Matcha Latte | D33: =VLOOKUP(C33, 'LIST HPP'!$B$4:$C$39, 2, ) -> 8805.63 | E33: 1 | G33: =SUM(E33:F33) -> 1 | H33: =D33*G33 -> 8805.63 | I33: =sum(H33:H63) -> 282415.13 | J33: 469582 | K33: =(J33-I33)/J33 -> 0.39858187 | L33: =J33-I33 -> 187166.87
C34: Hojicha Latte | D34: =VLOOKUP(C34, 'LIST HPP'!$B$4:$C$39, 2, ) -> 8150.63 | E34: 0 | G34: =SUM(E34:F34) -> 0 | H34: =D34*G34 -> 0
C35: Choco Latte | D35: =VLOOKUP(C35, 'LIST HPP'!$B$4:$C$39, 2, ) -> 6013.63 | E35: 0 | G35: =SUM(E35:F35) -> 0 | H35: =D35*G35 -> 0
C36: Choco Ichigo Latte | D36: =VLOOKUP(C36, 'LIST HPP'!$B$4:$C$39, 2, ) -> 7131.43 | E36: 0 | G36: =SUM(E36:F36) -> 0 | H36: =D36*G36 -> 0
C37: Matcha Tea | D37: =VLOOKUP(C37, 'LIST HPP'!$B$4:$C$39, 2, ) -> 3748.21 | E37: 0 | G37: =SUM(E37:F37) -> 0 | H37: =D37*G37 -> 0
C38: Ice Tea | D38: =VLOOKUP(C38, 'LIST HPP'!$B$4:$C$39, 2, ) -> 1448.63 | E38: 0 | G38: =SUM(E38:F38) -> 0 | H38: =D38*G38 -> 0
C39: Gyumeshi | D39: =VLOOKUP(C39, 'LIST HPP'!$B$4:$C$39, 2, ) -> 11670 | E39: 1 | G39: =SUM(E39:F39) -> 1 | H39: =D39*G39 -> 11670
C40: Karage Don | D40: =VLOOKUP(C40, 'LIST HPP'!$B$4:$C$39, 2, ) -> 9350.16 | E40: 1 | G40: =SUM(E40:F40) -> 1 | H40: =D40*G40 -> 9350.16
C41: Hot Honey Karage Don | D41: =VLOOKUP(C41, 'LIST HPP'!$B$4:$C$39, 2, ) -> 9990.16 | E41: 0 | G41: =SUM(E41:F41) -> 0 | H41: =D41*G41 -> 0
C42: Chicken Katsu Don | D42: =VLOOKUP(C42, 'LIST HPP'!$B$4:$C$39, 2, ) -> 7445.2 | E42: 8 | G42: =SUM(E42:F42) -> 8 | H42: =D42*G42 -> 59561.6
C43: Gyuniku Ala Carte | D43: =VLOOKUP(C43, 'LIST HPP'!$B$4:$C$39, 2, ) -> 17260 | E43: 0 | G43: =SUM(E43:F43) -> 0 | H43: =D43*G43 -> 0
C44: Karage Ala Carte | D44: =VLOOKUP(C44, 'LIST HPP'!$B$4:$C$39, 2, ) -> 14155 | E44: 1 | G44: =SUM(E44:F44) -> 1 | H44: =D44*G44 -> 14155
C45: Hot Honey Karage Ala Carte | D45: =VLOOKUP(C45, 'LIST HPP'!$B$4:$C$39, 2, ) -> 15435 | E45: 0 | G45: =SUM(E45:F45) -> 0 | H45: =D45*G45 -> 0
... C63: Gyuniku Bento | D63: =VLOOKUP(C63, 'LIST HPP'!$B$4:$C$39, 2, ) -> 14616.31 | E63: 0 | G63: =SUM(E63:F63) -> 0 | H63: =D63*G63 -> 0
A64: GOJEK | C64: Matcha Latte | D64: =VLOOKUP(C64, 'LIST HPP'!$B$4:$C$39, 2, ) -> 8805.63 | E64: 0 | G64: =Sum(E64:F64) -> 0 | H64: =D64*G64 -> 0 | I64: =sum(H64:H94) -> 28518.31 | J64: 66475 | K64: =(J64-I64)/J64 -> 0.57099195 | L64: =J64-I64 -> 37956.69
C65: Hojicha Latte | D65: =VLOOKUP(C65, 'LIST HPP'!$B$4:$C$39, 2, ) -> 8150.63 | E65: 0 | G65: =Sum(E65:F65) -> 0 | H65: =D65*G65 -> 0
C66: Choco Latte | D66: =VLOOKUP(C66, 'LIST HPP'!$B$4:$C$39, 2, ) -> 6013.63 | E66: 0 | G66: =Sum(E66:F66) -> 0 | H66: =D66*G66 -> 0
C67: Choco Ichigo Latte | D67: =VLOOKUP(C67, 'LIST HPP'!$B$4:$C$39, 2, ) -> 7131.43 | E67: 0 | G67: =Sum(E67:F67) -> 0 | H67: =D67*G67 -> 0
C68: Matcha Tea | D68: =VLOOKUP(C68, 'LIST HPP'!$B$4:$C$39, 2, ) -> 3748.21 | E68: 1 | G68: =Sum(E68:F68) -> 1 | H68: =D68*G68 -> 3748.21
C69: Ice Tea | D69: =VLOOKUP(C69, 'LIST HPP'!$B$4:$C$39, 2, ) -> 1448.63 | E69: 0 | G69: =Sum(E69:F69) -> 0 | H69: =D69*G69 -> 0
C70: Gyumeshi | D70: =VLOOKUP(C70, 'LIST HPP'!$B$4:$C$39, 2, ) -> 11670 | E70: 0 | G70: =Sum(E70:F70) -> 0 | H70: =D70*G70 -> 0
C71: Karage Don | D71: =VLOOKUP(C71, 'LIST HPP'!$B$4:$C$39, 2, ) -> 9350.16 | E71: 0 | G71: =Sum(E71:F71) -> 0 | H71: =D71*G71 -> 0
C72: Hot Honey Karage Don | D72: =VLOOKUP(C72, 'LIST HPP'!$B$4:$C$39, 2, ) -> 9990.16 | E72: 0 | G72: =Sum(E72:F72) -> 0 | H72: =D72*G72 -> 0
C73: Chicken Katsu Don | D73: =VLOOKUP(C73, 'LIST HPP'!$B$4:$C$39, 2, ) -> 7445.2 | E73: 3 | G73: =Sum(E73:F73) -> 3 | H73: =D73*G73 -> 22335.6
C74: Gyuniku Ala Carte | D74: =VLOOKUP(C74, 'LIST HPP'!$B$4:$C$39, 2, ) -> 17260 | E74: 0 | G74: =Sum(E74:F74) -> 0 | H74: =D74*G74 -> 0
...

Sheet 16062026
A1: PLATFORM | B1: Tanggal | C1: Nama Item | D1: HPP | E1: Jumlah | F1: Jumlah QR | G1: Total Jumlah | H1: Total | I1: Total HPP | J1: Uang Masuk | K1: Margin | L1: Gross Profit
A2: SHOPEE | C2: Matcha Latte | D2: =VLOOKUP(C2, 'LIST HPP'!$B$4:$C$39, 2, ) -> 8805.63 | E2: 0 | G2: =sum(E2:F2) -> 0 | H2: =D2*G2 -> 0 | I2: =sum(H2:H32) -> 789122.4 | J2: 1301577 | K2: =(J2-I2)/J2 -> 0.39371824 | L2: =J2-I2 -> 512454.6
C3: Hojicha Latte | D3: =VLOOKUP(C3, 'LIST HPP'!$B$4:$C$39, 2, ) -> 8150.63 | E3: 0 | G3: =sum(E3:F3) -> 0 | H3: =D3*G3 -> 0
C4: Choco Latte | D4: =VLOOKUP(C4, 'LIST HPP'!$B$4:$C$39, 2, ) -> 6013.63 | E4: 2 | G4: =sum(E4:F4) -> 2 | H4: =D4*G4 -> 12027.26
C5: Choco Ichigo Latte | D5: =VLOOKUP(C5, 'LIST HPP'!$B$4:$C$39, 2, ) -> 7131.43 | E5: 2 | G5: =sum(E5:F5) -> 2 | H5: =D5*G5 -> 14262.86
C6: Matcha Tea | D6: =VLOOKUP(C6, 'LIST HPP'!$B$4:$C$39, 2, ) -> 3748.21 | E6: 5 | G6: =sum(E6:F6) -> 5 | H6: =D6*G6 -> 18741.05
